Workbook
Name CycleWork: 'الإعدادات والقوائم'!$B$3
Name CycleRest: 'الإعدادات والقوائم'!$B$4
Name MinStaff: 'الإعدادات والقوائم'!$B$5
Name MaxLeave: 'الإعدادات والقوائم'!$B$6
Name StartShift: 'الإعدادات والقوائم'!$B$7
Name LeaveTypes: 'الإعدادات والقوائم'!$D$2:$D$7
Name ReqStatus: 'الإعدادات والقوائم'!$F$2:$F$4
Name Holidays: 'الإعدادات والقوائم'!$K$2:$K$21
Name EmpNames: 'الموظفون'!$B$2:$B$9

Sheet لوحة المعلومات
B1: لوحة المعلومات — جدول الورديات وحجز الإجازات
B3: ="قسم العمليات الجمركية • آخر تحديث: "&TEXT(TODAY(),"DD/MM/YYYY")
B5: عدد الموظفين | F5: إجمالي الطلبات | J5: الطلبات المعتمدة | N5: طلبات فيها تعارض
B6: =COUNTA(EmpNames) | F6: =COUNTA('حجز الإجازات'!$B$5:$B$104) | J6: =COUNTIF('حجز الإجازات'!$G$5:$G$104,"معتمد") | N6: =COUNTIF('حجز الإجازات'!$H$5:$H$104,"*تعارض*")
B8: قيد الانتظار | F8: الطلبات المرفوضة | J8: إجمالي أيام الإجازات | N8: مُجازون اليوم
B9: =COUNTIF('حجز الإجازات'!$G$5:$G$104,"قيد الانتظار") | F9: =COUNTIF('حجز الإجازات'!$G$5:$G$104,"مرفوض") | J9: =SUMIFS('حجز الإجازات'!$F$5:$F$104,'حجز الإجازات'!$G$5:$G$104,"معتمد") | N9: =SUMPRODUCT(('حجز الإجازات'!$G$5:$G$104="معتمد")*('حجز الإجازات'!$D$5:$D$104<=TODAY())*('حجز الإجازات'!$E$5:$E$104>=TODAY()))
B11: وردية الفريق اليوم | J11: ➕ تسجيل إجازة جديدة (اضغط هنا)
B12: =IF(TODAY()<'الإعدادات والقوائم'!$B$2,"-",IF(MOD(TODAY()-'الإعدادات والقوائم'!$B$2,CycleWork+CycleRest)>=CycleWork,"راحة",INDEX('الإعدادات والقوائم'!$H$2:$H$4,MOD(INT(MOD(TODAY()-'الإعدادات والقوائم'!$B$2,CycleWork+CycleRest)*3/CycleWork)+MATCH(StartShift,'الإعدادات والقوائم'!$H$2:$H$4,0)-1,3)+1)))
B14: 📊 الإجازات حسب النوع
B15: النوع | C15: عدد الطلبات | D15: إجمالي الأيام
B16: سنوية | C16: =COUNTIF('حجز الإجازات'!$C$5:$C$104,"سنوية") | D16: =SUMIF('حجز الإجازات'!$C$5:$C$104,"سنوية",'حجز الإجازات'!$F$5:$F$104)
B17: عارض | C17: =COUNTIF('حجز الإجازات'!$C$5:$C$104,"عارض") | D17: =SUMIF('حجز الإجازات'!$C$5:$C$104,"عارض",'حجز الإجازات'!$F$5:$F$104)
B18: دورية | C18: =COUNTIF('حجز الإجازات'!$C$5:$C$104,"دورية") | D18: =SUMIF('حجز الإجازات'!$C$5:$C$104,"دورية",'حجز الإجازات'!$F$5:$F$104)
B19: مرضية | C19: =COUNTIF('حجز الإجازات'!$C$5:$C$104,"مرضية") | D19: =SUMIF('حجز الإجازات'!$C$5:$C$104,"مرضية",'حجز الإجازات'!$F$5:$F$104)
B20: مرافق مريض | C20: =COUNTIF('حجز الإجازات'!$C$5:$C$104,"مرافق مريض") | D20: =SUMIF('حجز الإجازات'!$C$5:$C$104,"مرافق مريض",'حجز الإجازات'!$F$5:$F$104)
B21: أخرى | C21: =COUNTIF('حجز الإجازات'!$C$5:$C$104,"أخرى") | D21: =SUMIF('حجز الإجازات'!$C$5:$C$104,"أخرى",'حجز الإجازات'!$F$5:$F$104)
B31: 📊 إجمالي أيام الإجازة لكل موظف
B32: الموظف | C32: عدد الطلبات | D32: إجمالي الأيام
B33: ='الموظفون'!B2 | C33: =COUNTIFS('حجز الإجازات'!$B$5:$B$104,'الموظفون'!B2,'حجز الإجازات'!$G$5:$G$104,"<>مرفوض") | D33: =SUMIFS('حجز الإجازات'!$F$5:$F$104,'حجز الإجازات'!$B$5:$B$104,'الموظفون'!B2,'حجز الإجازات'!$G$5:$G$104,"<>مرفوض")
B34: ='الموظفون'!B3 | C34: =COUNTIFS('حجز الإجازات'!$B$5:$B$104,'الموظفون'!B3,'حجز الإجازات'!$G$5:$G$104,"<>مرفوض") | D34: =SUMIFS('حجز الإجازات'!$F$5:$F$104,'حجز الإجازات'!$B$5:$B$104,'الموظفون'!B3,'حجز الإجازات'!$G$5:$G$104,"<>مرفوض")
B35: ='الموظفون'!B4 | C35: =COUNTIFS('حجز الإجازات'!$B$5:$B$104,'الموظفون'!B4,'حجز الإجازات'!$G$5:$G$104,"<>مرفوض") | D35: =SUMIFS('حجز الإجازات'!$F$5:$F$104,'حجز الإجازات'!$B$5:$B$104,'الموظفون'!B4,'حجز الإجازات'!$G$5:$G$104,"<>مرفوض")
B36: ='الموظفون'!B5 | C36: =COUNTIFS('حجز الإجازات'!$B$5:$B$104,'الموظفون'!B5,'حجز الإجازات'!$G$5:$G$104,"<>مرفوض") | D36: =SUMIFS('حجز الإجازات'!$F$5:$F$104,'حجز الإجازات'!$B$5:$B$104,'الموظفون'!B5,'حجز الإجازات'!$G$5:$G$104,"<>مرفوض")
B37: ='الموظفون'!B6 | C37: =COUNTIFS('حجز الإجازات'!$B$5:$B$104,'الموظفون'!B6,'حجز الإجازات'!$G$5:$G$104,"<>مرفوض") | D37: =SUMIFS('حجز الإجازات'!$F$5:$F$104,'حجز الإجازات'!$B$5:$B$104,'الموظفون'!B6,'حجز الإجازات'!$G$5:$G$104,"<>مرفوض")
B38: ='الموظفون'!B7 | C38: =COUNTIFS('حجز الإجازات'!$B$5:$B$104,'الموظفون'!B7,'حجز الإجازات'!$G$5:$G$104,"<>مرفوض") | D38: =SUMIFS('حجز الإجازات'!$F$5:$F$104,'حجز الإجازات'!$B$5:$B$104,'الموظفون'!B7,'حجز الإجازات'!$G$5:$G$104,"<>مرفوض")
B39: ='الموظفون'!B8 | C39: =COUNTIFS('حجز الإجازات'!$B$5:$B$104,'الموظفون'!B8,'حجز الإجازات'!$G$5:$G$104,"<>مرفوض") | D39: =SUMIFS('حجز الإجازات'!$F$5:$F$104,'حجز الإجازات'!$B$5:$B$104,'الموظفون'!B8,'حجز الإجازات'!$G$5:$G$104,"<>مرفوض")
B40: ='الموظفون'!B9 | C40: =COUNTIFS('حجز الإجازات'!$B$5:$B$104,'الموظفون'!B9,'حجز الإجازات'!$G$5:$G$104,"<>مرفوض") | D40: =SUMIFS('حجز الإجازات'!$F$5:$F$104,'حجز الإجازات'!$B$5:$B$104,'الموظفون'!B9,'حجز الإجازات'!$G$5:$G$104,"<>مرفوض")
B47: 🥧 توزيع الطلبات حسب الحالة
B48: الحالة | C48: عدد الطلبات
B49: معتمد | C49: =COUNTIF('حجز الإجازات'!$G$5:$G$104,"معتمد")
B50: قيد الانتظار | C50: =COUNTIF('حجز الإجازات'!$G$5:$G$104,"قيد الانتظار")
B51: مرفوض | C51: =COUNTIF('حجز الإجازات'!$G$5:$G$104,"مرفوض")

Sheet تعليمات
B1: نظام جدول الورديات وحجز الإجازات
B2: قسم العمليات الجمركية — فريق الوردية
B4: محتويات الملف (الأوراق بالأسفل):
B5: 1) الموظفون: قائمة أفراد الفريق وأرقامهم الوظيفية وبداية دورة العمل لكل فرد.
B6: 2) جدول الورديات: تقويم يومي يحسب تلقائياً (عمل / راحة) ويُظهر الإجازات المعتمدة بالألوان.
B7: 3) تقويم الإجازات: عرض واضح للإجازات المعتمدة فقط (موظفون × أيام) مع إجمالي أيام كل موظف.
B8: 4) حجز الإجازات: تُسجَّل فيه طلبات الإجازة، ويكشف التعارض تلقائياً.
B9: 5) الإعدادات والقوائم: ضبط بداية الدورة والحد الأدنى للتغطية وأنواع الإجازات.
B11: نظام الدوام:
B12: • 6 أيام عمل متتالية ثم 4 أيام راحة (دورية) — دورة كل 10 أيام.
B13: • ثلاث ورديات (زامات): صباح ← عصر ← ليل.
B14: صباح: 6:00 ص ← 1:00 م | عصر: 1:00 م ← 9:00 م | ليل: 9:00 م ← 6:00 ص (اليوم التالي).
... B32: • كل التواريخ بصيغة يوم/شهر/سنة. عدّل «بداية الفترة» وعدد الموظفين بحرية.

Sheet الإعدادات والقوائم
A1: الإعدادات العامة | D1: أنواع الإجازات | F1: حالات الطلب | H1: الوردية | I1: التوقيت | K1: تاريخ العطلة | L1: المناسبة
A2: بداية فترة الجدول | B2: 46187 | D2: سنوية | F2: معتمد | H2: صباح | I2: 6:00 ص ← 1:00 م | K2: 46374 | L2: اليوم الوطني
A3: طول دورة العمل (أيام) | B3: 6 | D3: عارض | F3: قيد الانتظار | H3: عصر | I3: 1:00 م ← 9:00 م | K3: 46427 | L3: اليوم الرياضي للدولة
A4: طول الراحة الدورية (أيام) | B4: 4 | D4: دورية | F4: مرفوض | H4: ليل | I4: 9:00 م ← 6:00 ص (اليوم التالي)
A5: الحد الأدنى للعاملين يومياً | B5: 4 | D5: مرضية
A6: أقصى عدد مُجازين في اليوم | B6: 3 | D6: مرافق مريض
A7: وردية بداية الفريق | B7: صباح | D7: أخرى

Sheet الموظفون
A1: م | B1: الاسم | C1: الرقم الوظيفي | D1: بداية الدورة
A2: 1 | B2: سالم شليويح المري | C2: 392 | D2: 46187
A3: 2 | B3: فهد عبدالعزيز عبدالله | C3: 2306 | D3: 46187
A4: 3 | B4: محمد ناصر الغانم | C4: 4756 | D4: 46187
A5: 4 | B5: راشد عيسى التميمي | C5: 4749 | D5: 46187
A6: 5 | B6: طلال زايد المري | C6: 2927 | D6: 46187
A7: 6 | B7: منصور مبارك الجابري | C7: 4522 | D7: 46187
A8: 7 | B8: محمد حمد الجابر | C8: 3317 | D8: 46187
A9: 8 | B9: عبدالله سعد المهندي | C9: 2424 | D9: 46187

Sheet حجز الإجازات
A1: حجز الإجازات — قسم العمليات الجمركية
A2: سجّل الطلب ثم تأكد من خانتي «فحص التعارض» و«تنبيه التغطية» قبل الاعتماد. | H2: ↩ الرجوع للوحة المعلومات | L2: ⚡ إدخال سريع (لزر الماكرو)
L3: الاسم
A4: رقم الطلب | B4: اسم الموظف | C4: نوع الإجازة | D4: من تاريخ | E4: إلى تاريخ | F4: عدد الأيام | G4: الحالة | H4: فحص التعارض | I4: تنبيه التغطية | J4: ملاحظات | L4: النوع
A5: 1 | B5: سالم شليويح المري | C5: دورية | D5: 46190 | E5: 46192 | F5: =IF(OR($D5="",$E5=""),"",$E5-$D5+1-SUMPRODUCT((Holidays>=$D5)*(Holidays<=$E5))) | G5: معتمد | H5: =IF(OR($B5="",$D5="",$E5=""),"",IF(SUMPRODUCT(('حجز الإجازات'!$B$5:$B$104=$B5)*('حجز الإجازات'!$G$5:$G$104<>"مرفوض")*('حجز الإجازات'!$D$5:$D$104<=$E5)*($D5<=('حجز الإجازات'!$E$5:$E$104)))-(($B5<>"")*($G5<>"مرفوض"))>0,"⚠ تعارض","✓ سليم")) | I5: =IF($D5="","",IF(SUMPRODUCT(('حجز الإجازات'!$G$5:$G$104<>"مرفوض")*('حجز الإجازات'!$D$5:$D$104<=$D5)*($D5<=('حجز الإجازات'!$E$5:$E$104)))>MaxLeave,"⚠ مجازين "&SUMPRODUCT(('حجز الإجازات'!$G$5:$G$104<>"مرفوض")*('حجز الإجازات'!$D$5:$D$104<=$D5)*($D5<=('حجز الإجازات'!$E$5:$E$104)))&" / الحد "&MaxLeave,"✓ مجازين "&SUMPRODUCT(('حجز الإجازات'!$G$5:$G$104<>"مرفوض")*('حجز الإجازات'!$D$5:$D$104<=$D5)*($D5<=('حجز الإجازات'!$E$5:$E$104)))&" / الحد "&MaxLeave)) | L5: من تاريخ
A6: 2 | B6: فهد عبدالعزيز عبدالله | C6: سنوية | D6: 46191 | E6: 46192 | F6: =IF(OR($D6="",$E6=""),"",$E6-$D6+1-SUMPRODUCT((Holidays>=$D6)*(Holidays<=$E6))) | G6: معتمد | H6: =IF(OR($B6="",$D6="",$E6=""),"",IF(SUMPRODUCT(('حجز الإجازات'!$B$5:$B$104=$B6)*('حجز الإجازات'!$G$5:$G$104<>"مرفوض")*('حجز الإجازات'!$D$5:$D$104<=$E6)*($D6<=('حجز الإجازات'!$E$5:$E$104)))-(($B6<>"")*($G6<>"مرفوض"))>0,"⚠ تعارض","✓ سليم")) | I6: =IF($D6="","",IF(SUMPRODUCT(('حجز الإجازات'!$G$5:$G$104<>"مرفوض")*('حجز الإجازات'!$D$5:$D$104<=$D6)*($D6<=('حجز الإجازات'!$E$5:$E$104)))>MaxLeave,"⚠ مجازين "&SUMPRODUCT(('حجز الإجازات'!$G$5:$G$104<>"مرفوض")*('حجز الإجازات'!$D$5:$D$104<=$D6)*($D6<=('حجز الإجازات'!$E$5:$E$104)))&" / الحد "&MaxLeave,"✓ مجازين "&SUMPRODUCT(('حجز الإجازات'!$G$5:$G$104<>"مرفوض")*('حجز الإجازات'!$D$5:$D$104<=$D6)*($D6<=('حجز الإجازات'!$E$5:$E$104)))&" / الحد "&MaxLeave)) | L6: إلى تاريخ
A7: 3 | B7: محمد ناصر الغانم | C7: دورية | D7: 46201 | E7: 46205 | F7: =IF(OR($D7="",$E7=""),"",$E7-$D7+1-SUMPRODUCT((Holidays>=$D7)*(Holidays<=$E7))) | G7: معتمد | H7: =IF(OR($B7="",$D7="",$E7=""),"",IF(SUMPRODUCT(('حجز الإجازات'!$B$5:$B$104=$B7)*('حجز الإجازات'!$G$5:$G$104<>"مرفوض")*('حجز الإجازات'!$D$5:$D$104<=$E7)*($D7<=('حجز الإجازات'!$E$5:$E$104)))-(($B7<>"")*($G7<>"مرفوض"))>0,"⚠ تعارض","✓ سليم")) | I7: =IF($D7="","",IF(SUMPRODUCT(('حجز الإجازات'!$G$5:$G$104<>"مرفوض")*('حجز الإجازات'!$D$5:$D$104<=$D7)*($D7<=('حجز الإجازات'!$E$5:$E$104)))>MaxLeave,"⚠ مجازين "&SUMPRODUCT(('حجز الإجازات'!$G$5:$G$104<>"مرفوض")*('حجز الإجازات'!$D$5:$D$104<=$D7)*($D7<=('حجز الإجازات'!$E$5:$E$104)))&" / الحد "&MaxLeave,"✓ مجازين "&SUMPRODUCT(('حجز الإجازات'!$G$5:$G$104<>"مرفوض")*('حجز الإجازات'!$D$5:$D$104<=$D7)*($D7<=('حجز الإجازات'!$E$5:$E$104)))&" / الحد "&MaxLeave)) | L7: الحالة
A8: 4 | B8: محمد ناصر الغانم | C8: دورية | D8: 46208 | E8: 46212 | F8: =IF(OR($D8="",$E8=""),"",$E8-$D8+1-SUMPRODUCT((Holidays>=$D8)*(Holidays<=$E8))) | G8: معتمد | H8: =IF(OR($B8="",$D8="",$E8=""),"",IF(SUMPRODUCT(('حجز الإجازات'!$B$5:$B$104=$B8)*('حجز الإجازات'!$G$5:$G$104<>"مرفوض")*('حجز الإجازات'!$D$5:$D$104<=$E8)*($D8<=('حجز الإجازات'!$E$5:$E$104)))-(($B8<>"")*($G8<>"مرفوض"))>0,"⚠ تعارض","✓ سليم")) | I8: =IF($D8="","",IF(SUMPRODUCT(('حجز الإجازات'!$G$5:$G$104<>"مرفوض")*('حجز الإجازات'!$D$5:$D$104<=$D8)*($D8<=('حجز الإجازات'!$E$5:$E$104)))>MaxLeave,"⚠ مجازين "&SUMPRODUCT(('حجز الإجازات'!$G$5:$G$104<>"مرفوض")*('حجز الإجازات'!$D$5:$D$104<=$D8)*($D8<=('حجز الإجازات'!$E$5:$E$104)))&" / الحد "&MaxLeave,"✓ مجازين "&SUMPRODUCT(('حجز الإجازات'!$G$5:$G$104<>"مرفوض")*('حجز الإجازات'!$D$5:$D$104<=$D8)*($D8<=('حجز الإجازات'!$E$5:$E$104)))&" / الحد "&MaxLeave)) | L8: املأ ثم اضغط زر «حفظ الإجازة»
A9: 5 | B9: منصور مبارك الجابري | C9: سنوية | D9: 46207 | E9: 46212 | F9: =IF(OR($D9="",$E9=""),"",$E9-$D9+1-SUMPRODUCT((Holidays>=$D9)*(Holidays<=$E9))) | G9: معتمد | H9: =IF(OR($B9="",$D9="",$E9=""),"",IF(SUMPRODUCT(('حجز الإجازات'!$B$5:$B$104=$B9)*('حجز الإجازات'!$G$5:$G$104<>"مرفوض")*('حجز الإجازات'!$D$5:$D$104<=$E9)*($D9<=('حجز الإجازات'!$E$5:$E$104)))-(($B9<>"")*($G9<>"مرفوض"))>0,"⚠ تعارض","✓ سليم")) | I9: =IF($D9="","",IF(SUMPRODUCT(('حجز الإجازات'!$G$5:$G$104<>"مرفوض")*('حجز الإجازات'!$D$5:$D$104<=$D9)*($D9<=('حجز الإجازات'!$E$5:$E$104)))>MaxLeave,"⚠ مجازين "&SUMPRODUCT(('حجز الإجازات'!$G$5:$G$104<>"مرفوض")*('حجز الإجازات'!$D$5:$D$104<=$D9)*($D9<=('حجز الإجازات'!$E$5:$E$104)))&" / الحد "&MaxLeave,"✓ مجازين "&SUMPRODUCT(('حجز الإجازات'!$G$5:$G$104<>"مرفوض")*('حجز الإجازات'!$D$5:$D$104<=$D9)*($D9<=('حجز الإجازات'!$E$5:$E$104)))&" / الحد "&MaxLeave))
A10: 6 | B10: منصور مبارك الجابري | C10: سنوية | D10: 46191 | E10: 46192 | F10: =IF(OR($D10="",$E10=""),"",$E10-$D10+1-SUMPRODUCT((Holidays>=$D10)*(Holidays<=$E10))) | G10: معتمد | H10: =IF(OR($B10="",$D10="",$E10=""),"",IF(SUMPRODUCT(('حجز الإجازات'!$B$5:$B$104=$B10)*('حجز الإجازات'!$G$5:$G$104<>"مرفوض")*('حجز الإجازات'!$D$5:$D$104<=$E10)*($D10<=('حجز الإجازات'!$E$5:$E$104)))-(($B10<>"")*($G10<>"مرفوض"))>0,"⚠ تعارض","✓ سليم")) | I10: =IF($D10="","",IF(SUMPRODUCT(('حجز الإجازات'!$G$5:$G$104<>"مرفوض")*('حجز الإجازات'!$D$5:$D$104<=$D10)*($D10<=('حجز الإجازات'!$E$5:$E$104)))>MaxLeave,"⚠ مجازين "&SUMPRODUCT(('حجز الإجازات'!$G$5:$G$104<>"مرفوض")*('حجز الإجازات'!$D$5:$D$104<=$D10)*($D10<=('حجز الإجازات'!$E$5:$E$104)))&" / الحد "&MaxLeave,"✓ مجازين "&SUMPRODUCT(('حجز الإجازات'!$G$5:$G$104<>"مرفوض")*('حجز الإجازات'!$D$5:$D$104<=$D10)*($D10<=('حجز الإجازات'!$E$5:$E$104)))&" / الحد "&MaxLeave))
A11: 7 | B11: محمد حمد الجابر | C11: سنوية | D11: 46190 | E11: 46192 | F11: =IF(OR($D11="",$E11=""),"",$E11-$D11+1-SUMPRODUCT((Holidays>=$D11)*(Holidays<=$E11))) | G11: معتمد | H11: =IF(OR($B11="",$D11="",$E11=""),"",IF(SUMPRODUCT(('حجز الإجازات'!$B$5:$B$104=$B11)*('حجز الإجازات'!$G$5:$G$104<>"مرفوض")*('حجز الإجازات'!$D$5:$D$104<=$E11)*($D11<=('حجز الإجازات'!$E$5:$E$104)))-(($B11<>"")*($G11<>"مرفوض"))>0,"⚠ تعارض","✓ سليم")) | I11: =IF($D11="","",IF(SUMPRODUCT(('حجز الإجازات'!$G$5:$G$104<>"مرفوض")*('حجز الإجازات'!$D$5:$D$104<=$D11)*($D11<=('حجز الإجازات'!$E$5:$E$104)))>MaxLeave,"⚠ مجازين "&SUMPRODUCT(('حجز الإجازات'!$G$5:$G$104<>"مرفوض")*('حجز الإجازات'!$D$5:$D$104<=$D11)*($D11<=('حجز الإجازات'!$E$5:$E$104)))&" / الحد "&MaxLeave,"✓ مجازين "&SUMPRODUCT(('حجز الإجازات'!$G$5:$G$104<>"مرفوض")*('حجز الإجازات'!$D$5:$D$104<=$D11)*($D11<=('حجز الإجازات'!$E$5:$E$104)))&" / الحد "&MaxLeave))
A12: 8 | B12: عبدالله سعد المهندي | C12: مرافق مريض | D12: 46190 | E12: 46233 | F12: =IF(OR($D12="",$E12=""),"",$E12-$D12+1-SUMPRODUCT((Holidays>=$D12)*(Holidays<=$E12))) | G12: معتمد | H12: =IF(OR($B12="",$D12="",$E12=""),"",IF(SUMPRODUCT(('حجز الإجازات'!$B$5:$B$104=$B12)*('حجز الإجازات'!$G$5:$G$104<>"مرفوض")*('حجز الإجازات'!$D$5:$D$104<=$E12)*($D12<=('حجز الإجازات'!$E$5:$E$104)))-(($B12<>"")*($G12<>"مرفوض"))>0,"⚠ تعارض","✓ سليم")) | I12: =IF($D12="","",IF(SUMPRODUCT(('حجز الإجازات'!$G$5:$G$104<>"مرفوض")*('حجز الإجازات'!$D$5:$D$104<=$D12)*($D12<=('حجز الإجازات'!$E$5:$E$104)))>MaxLeave,"⚠ مجازين "&SUMPRODUCT(('حجز الإجازات'!$G$5:$G$104<>"مرفوض")*('حجز الإجازات'!$D$5:$D$104<=$D12)*($D12<=('حجز الإجازات'!$E$5:$E$104)))&" / الحد "&MaxLeave,"✓ مجازين "&SUMPRODUCT(('حجز الإجازات'!$G$5:$G$104<>"مرفوض")*('حجز الإجازات'!$D$5:$D$104<=$D12)*($D12<=('حجز الإجازات'!$E$5:$E$104)))&" / الحد "&MaxLeave))
A13: 9 | B13: راشد عيسى التميمي | C13: سنوية | D13: 46207 | E13: 46212 | F13: =IF(OR($D13="",$E13=""),"",$E13-$D13+1-SUMPRODUCT((Holidays>=$D13)*(Holidays<=$E13))) | G13: معتمد | H13: =IF(OR($B13="",$D13="",$E13=""),"",IF(SUMPRODUCT(('حجز الإجازات'!$B$5:$B$104=$B13)*('حجز الإجازات'!$G$5:$G$104<>"مرفوض")*('حجز الإجازات'!$D$5:$D$104<=$E13)*($D13<=('حجز الإجازات'!$E$5:$E$104)))-(($B13<>"")*($G13<>"مرفوض"))>0,"⚠ تعارض","✓ سليم")) | I13: =IF($D13="","",IF(SUMPRODUCT(('حجز الإجازات'!$G$5:$G$104<>"مرفوض")*('حجز الإجازات'!$D$5:$D$104<=$D13)*($D13<=('حجز الإجازات'!$E$5:$E$104)))>MaxLeave,"⚠ مجازين "&SUMPRODUCT(('حجز الإجازات'!$G$5:$G$104<>"مرفوض")*('حجز الإجازات'!$D$5:$D$104<=$D13)*($D13<=('حجز الإجازات'!$E$5:$E$104)))&" / الحد "&MaxLeave,"✓ مجازين "&SUMPRODUCT(('حجز الإجازات'!$G$5:$G$104<>"مرفوض")*('حجز الإجازات'!$D$5:$D$104<=$D13)*($D13<=('حجز الإجازات'!$E$5:$E$104)))&" / الحد "&MaxLeave))
A14: 10 | B14: راشد عيسى التميمي | C14: عارض | D14: 46217 | E14: 46217 | F14: =IF(OR($D14="",$E14=""),"",$E14-$D14+1-SUMPRODUCT((Holidays>=$D14)*(Holidays<=$E14))) | G14: معتمد | H14: =IF(OR($B14="",$D14="",$E14=""),"",IF(SUMPRODUCT(('حجز الإجازات'!$B$5:$B$104=$B14)*('حجز الإجازات'!$G$5:$G$104<>"مرفوض")*('حجز الإجازات'!$D$5:$D$104<=$E14)*($D14<=('حجز الإجازات'!$E$5:$E$104)))-(($B14<>"")*($G14<>"مرفوض"))>0,"⚠ تعارض","✓ سليم")) | I14: =IF($D14="","",IF(SUMPRODUCT(('حجز الإجازات'!$G$5:$G$104<>"مرفوض")*('حجز الإجازات'!$D$5:$D$104<=$D14)*($D14<=('حجز الإجازات'!$E$5:$E$104)))>MaxLeave,"⚠ مجازين "&SUMPRODUCT(('حجز الإجازات'!$G$5:$G$104<>"مرفوض")*('حجز الإجازات'!$D$5:$D$104<=$D14)*($D14<=('حجز الإجازات'!$E$5:$E$104)))&" / الحد "&MaxLeave,"✓ مجازين "&SUMPRODUCT(('حجز الإجازات'!$G$5:$G$104<>"مرفوض")*('حجز الإجازات'!$D$5:$D$104<=$D14)*($D14<=('حجز الإجازات'!$E$5:$E$104)))&" / الحد "&MaxLeave))
A15: 11 | B15: راشد عيسى التميمي | C15: سنوية | D15: 46218 | E15: 46222 | F15: =IF(OR($D15="",$E15=""),"",$E15-$D15+1-SUMPRODUCT((Holidays>=$D15)*(Holidays<=$E15))) | G15: معتمد | H15: =IF(OR($B15="",$D15="",$E15=""),"",IF(SUMPRODUCT(('حجز الإجازات'!$B$5:$B$104=$B15)*('حجز الإجازات'!$G$5:$G$104<>"مرفوض")*('حجز الإجازات'!$D$5:$D$104<=$E15)*($D15<=('حجز الإجازات'!$E$5:$E$104)))-(($B15<>"")*($G15<>"مرفوض"))>0,"⚠ تعارض","✓ سليم")) | I15: =IF($D15="","",IF(SUMPRODUCT(('حجز الإجازات'!$G$5:$G$104<>"مرفوض")*('حجز الإجازات'!$D$5:$D$104<=$D15)*($D15<=('حجز الإجازات'!$E$5:$E$104)))>MaxLeave,"⚠ مجازين "&SUMPRODUCT(('حجز الإجازات'!$G$5:$G$104<>"مرفوض")*('حجز الإجازات'!$D$5:$D$104<=$D15)*($D15<=('حجز الإجازات'!$E$5:$E$104)))&" / الحد "&MaxLeave,"✓ مجازين "&SUMPRODUCT(('حجز الإجازات'!$G$5:$G$104<>"مرفوض")*('حجز الإجازات'!$D$5:$D$104<=$D15)*($D15<=('حجز الإجازات'!$E$5:$E$104)))&" / الحد "&MaxLeave))
A16: 12 | B16: راشد عيسى التميمي | C16: أخرى | D16: 46190 | E16: 46190 | F16: =IF(OR($D16="",$E16=""),"",$E16-$D16+1-SUMPRODUCT((Holidays>=$D16)*(Holidays<=$E16))) | G16: معتمد | H16: =IF(OR($B16="",$D16="",$E16=""),"",IF(SUMPRODUCT(('حجز الإجازات'!$B$5:$B$104=$B16)*('حجز الإجازات'!$G$5:$G$104<>"مرفوض")*('حجز الإجازات'!$D$5:$D$104<=$E16)*($D16<=('حجز الإجازات'!$E$5:$E$104)))-(($B16<>"")*($G16<>"مرفوض"))>0,"⚠ تعارض","✓ سليم")) | I16: =IF($D16="","",IF(SUMPRODUCT(('حجز الإجازات'!$G$5:$G$104<>"مرفوض")*('حجز الإجازات'!$D$5:$D$104<=$D16)*($D16<=('حجز الإجازات'!$E$5:$E$104)))>MaxLeave,"⚠ مجازين "&SUMPRODUCT(('حجز الإجازات'!$G$5:$G$104<>"مرفوض")*('حجز الإجازات'!$D$5:$D$104<=$D16)*($D16<=('حجز الإجازات'!$E$5:$E$104)))&" / الحد "&MaxLeave,"✓ مجازين "&SUMPRODUCT(('حجز الإجازات'!$G$5:$G$104<>"مرفوض")*('حجز الإجازات'!$D$5:$D$104<=$D16)*($D16<=('حجز الإجازات'!$E$5:$E$104)))&" / الحد "&MaxLeave))
A17: 13 | F17: =IF(OR($D17="",$E17=""),"",$E17-$D17+1-SUMPRODUCT((Holidays>=$D17)*(Holidays<=$E17))) | H17: =IF(OR($B17="",$D17="",$E17=""),"",IF(SUMPRODUCT(('حجز الإجازات'!$B$5:$B$104=$B17)*('حجز الإجازات'!$G$5:$G$104<>"مرفوض")*('حجز الإجازات'!$D$5:$D$104<=$E17)*($D17<=('حجز الإجازات'!$E$5:$E$104)))-(($B17<>"")*($G17<>"مرفوض"))>0,"⚠ تعارض","✓ سليم")) | I17: =IF($D17="","",IF(SUMPRODUCT(('حجز الإجازات'!$G$5:$G$104<>"مرفوض")*('حجز الإجازات'!$D$5:$D$104<=$D17)*($D17<=('حجز الإجازات'!$E$5:$E$104)))>MaxLeave,"⚠ مجازين "&SUMPRODUCT(('حجز الإجازات'!$G$5:$G$104<>"مرفوض")*('حجز الإجازات'!$D$5:$D$104<=$D17)*($D17<=('حجز الإجازات'!$E$5:$E$104)))&" / الحد "&MaxLeave,"✓ مجازين "&SUMPRODUCT(('حجز الإجازات'!$G$5:$G$104<>"مرفوض")*('حجز الإجازات'!$D$5:$D$104<=$D17)*($D17<=('حجز الإجازات'!$E$5:$E$104)))&" / الحد "&MaxLeave))
A18: 14 | F18: =IF(OR($D18="",$E18=""),"",$E18-$D18+1-SUMPRODUCT((Holidays>=$D18)*(Holidays<=$E18))) | H18: =IF(OR($B18="",$D18="",$E18=""),"",IF(SUMPRODUCT(('حجز الإجازات'!$B$5:$B$104=$B18)*('حجز الإجازات'!$G$5:$G$104<>"مرفوض")*('حجز الإجازات'!$D$5:$D$104<=$E18)*($D18<=('حجز الإجازات'!$E$5:$E$104)))-(($B18<>"")*($G18<>"مرفوض"))>0,"⚠ تعارض","✓ سليم")) | I18: =IF($D18="","",IF(SUMPRODUCT(('حجز الإجازات'!$G$5:$G$104<>"مرفوض")*('حجز الإجازات'!$D$5:$D$104<=$D18)*($D18<=('حجز الإجازات'!$E$5:$E$104)))>MaxLeave,"⚠ مجازين "&SUMPRODUCT(('حجز الإجازات'!$G$5:$G$104<>"مرفوض")*('حجز الإجازات'!$D$5:$D$104<=$D18)*($D18<=('حجز الإجازات'!$E$5:$E$104)))&" / الحد "&MaxLeave,"✓ مجازين "&SUMPRODUCT(('حجز الإجازات'!$G$5:$G$104<>"مرفوض")*('حجز الإجازات'!$D$5:$D$104<=$D18)*($D18<=('حجز الإجازات'!$E$5:$E$104)))&" / الحد "&MaxLeave))
A19: 15 | F19: =IF(OR($D19="",$E19=""),"",$E19-$D19+1-SUMPRODUCT((Holidays>=$D19)*(Holidays<=$E19))) | H19: =IF(OR($B19="",$D19="",$E19=""),"",IF(SUMPRODUCT(('حجز الإجازات'!$B$5:$B$104=$B19)*('حجز الإجازات'!$G$5:$G$104<>"مرفوض")*('حجز الإجازات'!$D$5:$D$104<=$E19)*($D19<=('حجز الإجازات'!$E$5:$E$104)))-(($B19<>"")*($G19<>"مرفوض"))>0,"⚠ تعارض","✓ سليم")) | I19: =IF($D19="","",IF(SUMPRODUCT(('حجز الإجازات'!$G$5:$G$104<>"مرفوض")*('حجز الإجازات'!$D$5:$D$104<=$D19)*($D19<=('حجز الإجازات'!$E$5:$E$104)))>MaxLeave,"⚠ مجازين "&SUMPRODUCT(('حجز الإجازات'!$G$5:$G$104<>"مرفوض")*('حجز الإجازات'!$D$5:$D$104<=$D19)*($D19<=('حجز الإجازات'!$E$5:$E$104)))&" / الحد "&MaxLeave,"✓ مجازين "&SUMPRODUCT(('حجز الإجازات'!$G$5:$G$104<>"مرفوض")*('حجز الإجازات'!$D$5:$D$104<=$D19)*($D19<=('حجز الإجازات'!$E$5:$E$104)))&" / الحد "&MaxLeave))
A20: 16 | F20: =IF(OR($D20="",$E20=""),"",$E20-$D20+1-SUMPRODUCT((Holidays>=$D20)*(Holidays<=$E20))) | H20: =IF(OR($B20="",$D20="",$E20=""),"",IF(SUMPRODUCT(('حجز الإجازات'!$B$5:$B$104=$B20)*('حجز الإجازات'!$G$5:$G$104<>"مرفوض")*('حجز الإجازات'!$D$5:$D$104<=$E20)*($D20<=('حجز الإجازات'!$E$5:$E$104)))-(($B20<>"")*($G20<>"مرفوض"))>0,"⚠ تعارض","✓ سليم")) | I20: =IF($D20="","",IF(SUMPRODUCT(('حجز الإجازات'!$G$5:$G$104<>"مرفوض")*('حجز الإجازات'!$D$5:$D$104<=$D20)*($D20<=('حجز الإجازات'!$E$5:$E$104)))>MaxLeave,"⚠ مجازين "&SUMPRODUCT(('حجز الإجازات'!$G$5:$G$104<>"مرفوض")*('حجز الإجازات'!$D$5:$D$104<=$D20)*($D20<=('حجز الإجازات'!$E$5:$E$104)))&" / الحد "&MaxLeave,"✓ مجازين "&SUMPRODUCT(('حجز الإجازات'!$G$5:$G$104<>"مرفوض")*('حجز الإجازات'!$D$5:$D$104<=$D20)*($D20<=('حجز الإجازات'!$E$5:$E$104)))&" / الحد "&MaxLeave))
A21: 17 | F21: =IF(OR($D21="",$E21=""),"",$E21-$D21+1-SUMPRODUCT((Holidays>=$D21)*(Holidays<=$E21))) | H21: =IF(OR($B21="",$D21="",$E21=""),"",IF(SUMPRODUCT(('حجز الإجازات'!$B$5:$B$104=$B21)*('حجز الإجازات'!$G$5:$G$104<>"مرفوض")*('حجز الإجازات'!$D$5:$D$104<=$E21)*($D21<=('حجز الإجازات'!$E$5:$E$104)))-(($B21<>"")*($G21<>"مرفوض"))>0,"⚠ تعارض","✓ سليم")) | I21: =IF($D21="","",IF(SUMPRODUCT(('حجز الإجازات'!$G$5:$G$104<>"مرفوض")*('حجز الإجازات'!$D$5:$D$104<=$D21)*($D21<=('حجز الإجازات'!$E$5:$E$104)))>MaxLeave,"⚠ مجازين "&SUMPRODUCT(('حجز الإجازات'!$G$5:$G$104<>"مرفوض")*('حجز الإجازات'!$D$5:$D$104<=$D21)*($D21<=('حجز الإجازات'!$E$5:$E$104)))&" / الحد "&MaxLeave,"✓ مجازين "&SUMPRODUCT(('حجز الإجازات'!$G$5:$G$104<>"مرفوض")*('حجز الإجازات'!$D$5:$D$104<=$D21)*($D21<=('حجز الإجازات'!$E$5:$E$104)))&" / الحد "&MaxLeave))
A22: 18 | F22: =IF(OR($D22="",$E22=""),"",$E22-$D22+1-SUMPRODUCT((Holidays>=$D22)*(Holidays<=$E22))) | H22: =IF(OR($B22="",$D22="",$E22=""),"",IF(SUMPRODUCT(('حجز الإجازات'!$B$5:$B$104=$B22)*('حجز الإجازات'!$G$5:$G$104<>"مرفوض")*('حجز الإجازات'!$D$5:$D$104<=$E22)*($D22<=('حجز الإجازات'!$E$5:$E$104)))-(($B22<>"")*($G22<>"مرفوض"))>0,"⚠ تعارض","✓ سليم")) | I22: =IF($D22="","",IF(SUMPRODUCT(('حجز الإجازات'!$G$5:$G$104<>"مرفوض")*('حجز الإجازات'!$D$5:$D$104<=$D22)*($D22<=('حجز الإجازات'!$E$5:$E$104)))>MaxLeave,"⚠ مجازين "&SUMPRODUCT(('حجز الإجازات'!$G$5:$G$104<>"مرفوض")*('حجز الإجازات'!$D$5:$D$104<=$D22)*($D22<=('حجز الإجازات'!$E$5:$E$104)))&" / الحد "&MaxLeave,"✓ مجازين "&SUMPRODUCT(('حجز الإجازات'!$G$5:$G$104<>"مرفوض")*('حجز الإجازات'!$D$5:$D$104<=$D22)*($D22<=('حجز الإجازات'!$E$5:$E$104)))&" / الحد "&MaxLeave))
A23: 19 | F23: =IF(OR($D23="",$E23=""),"",$E23-$D23+1-SUMPRODUCT((Holidays>=$D23)*(Holidays<=$E23))) | H23: =IF(OR($B23="",$D23="",$E23=""),"",IF(SUMPRODUCT(('حجز الإجازات'!$B$5:$B$104=$B23)*('حجز الإجازات'!$G$5:$G$104<>"مرفوض")*('حجز الإجازات'!$D$5:$D$104<=$E23)*($D23<=('حجز الإجازات'!$E$5:$E$104)))-(($B23<>"")*($G23<>"مرفوض"))>0,"⚠ تعارض","✓ سليم")) | I23: =IF($D23="","",IF(SUMPRODUCT(('حجز الإجازات'!$G$5:$G$104<>"مرفوض")*('حجز الإجازات'!$D$5:$D$104<=$D23)*($D23<=('حجز الإجازات'!$E$5:$E$104)))>MaxLeave,"⚠ مجازين "&SUMPRODUCT(('حجز الإجازات'!$G$5:$G$104<>"مرفوض")*('حجز الإجازات'!$D$5:$D$104<=$D23)*($D23<=('حجز الإجازات'!$E$5:$E$104)))&" / الحد "&MaxLeave,"✓ مجازين "&SUMPRODUCT(('حجز الإجازات'!$G$5:$G$104<>"مرفوض")*('حجز الإجازات'!$D$5:$D$104<=$D23)*($D23<=('حجز الإجازات'!$E$5:$E$104)))&" / الحد "&MaxLeave))
A24: 20 | F24: =IF(OR($D24="",$E24=""),"",$E24-$D24+1-SUMPRODUCT((Holidays>=$D24)*(Holidays<=$E24))) | H24: =IF(OR($B24="",$D24="",$E24=""),"",IF(SUMPRODUCT(('حجز الإجازات'!$B$5:$B$104=$B24)*('حجز الإجازات'!$G$5:$G$104<>"مرفوض")*('حجز الإجازات'!$D$5:$D$104<=$E24)*($D24<=('حجز الإجازات'!$E$5:$E$104)))-(($B24<>"")*($G24<>"مرفوض"))>0,"⚠ تعارض","✓ سليم")) | I24: =IF($D24="","",IF(SUMPRODUCT(('حجز الإجازات'!$G$5:$G$104<>"مرفوض")*('حجز الإجازات'!$D$5:$D$104<=$D24)*($D24<=('حجز الإجازات'!$E$5:$E$104)))>MaxLeave,"⚠ مجازين "&SUMPRODUCT(('حجز الإجازات'!$G$5:$G$104<>"مرفوض")*('حجز الإجازات'!$D$5:$D$104<=$D24)*($D24<=('حجز الإجازات'!$E$5:$E$104)))&" / الحد "&MaxLeave,"✓ مجازين "&SUMPRODUCT(('حجز الإجازات'!$G$5:$G$104<>"مرفوض")*('حجز الإجازات'!$D$5:$D$104<=$D24)*($D24<=('حجز الإجازات'!$E$5:$E$104)))&" / الحد "&MaxLeave))
A25: 21 | F25: =IF(OR($D25="",$E25=""),"",$E25-$D25+1-SUMPRODUCT((Holidays>=$D25)*(Holidays<=$E25))) | H25: =IF(OR($B25="",$D25="",$E25=""),"",IF(SUMPRODUCT(('حجز الإجازات'!$B$5:$B$104=$B25)*('حجز الإجازات'!$G$5:$G$104<>"مرفوض")*('حجز الإجازات'!$D$5:$D$104<=$E25)*($D25<=('حجز الإجازات'!$E$5:$E$104)))-(($B25<>"")*($G25<>"مرفوض"))>0,"⚠ تعارض","✓ سليم")) | I25: =IF($D25="","",IF(SUMPRODUCT(('حجز الإجازات'!$G$5:$G$104<>"مرفوض")*('حجز الإجازات'!$D$5:$D$104<=$D25)*($D25<=('حجز الإجازات'!$E$5:$E$104)))>MaxLeave,"⚠ مجازين "&SUMPRODUCT(('حجز الإجازات'!$G$5:$G$104<>"مرفوض")*('حجز الإجازات'!$D$5:$D$104<=$D25)*($D25<=('حجز الإجازات'!$E$5:$E$104)))&" / الحد "&MaxLeave,"✓ مجازين "&SUMPRODUCT(('حجز الإجازات'!$G$5:$G$104<>"مرفوض")*('حجز الإجازات'!$D$5:$D$104<=$D25)*($D25<=('حجز الإجازات'!$E$5:$E$104)))&" / الحد "&MaxLeave))
A26: 22 | F26: =IF(OR($D26="",$E26=""),"",$E26-$D26+1-SUMPRODUCT((Holidays>=$D26)*(Holidays<=$E26))) | H26: =IF(OR($B26="",$D26="",$E26=""),"",IF(SUMPRODUCT(('حجز الإجازات'!$B$5:$B$104=$B26)*('حجز الإجازات'!$G$5:$G$104<>"مرفوض")*('حجز الإجازات'!$D$5:$D$104<=$E26)*($D26<=('حجز الإجازات'!$E$5:$E$104)))-(($B26<>"")*($G26<>"مرفوض"))>0,"⚠ تعارض","✓ سليم")) | I26: =IF($D26="","",IF(SUMPRODUCT(('حجز الإجازات'!$G$5:$G$104<>"مرفوض")*('حجز الإجازات'!$D$5:$D$104<=$D26)*($D26<=('حجز الإجازات'!$E$5:$E$104)))>MaxLeave,"⚠ مجازين "&SUMPRODUCT(('حجز الإجازات'!$G$5:$G$104<>"مرفوض")*('حجز الإجازات'!$D$5:$D$104<=$D26)*($D26<=('حجز الإجازات'!$E$5:$E$104)))&" / الحد "&MaxLeave,"✓ مجازين "&SUMPRODUCT(('حجز الإجازات'!$G$5:$G$104<>"مرفوض")*('حجز الإجازات'!$D$5:$D$104<=$D26)*($D26<=('حجز الإجازات'!$E$5:$E$104)))&" / الحد "&MaxLeave))
A27: 23 | F27: =IF(OR($D27="",$E27=""),"",$E27-$D27+1-SUMPRODUCT((Holidays>=$D27)*(Holidays<=$E27))) | H27: =IF(OR($B27="",$D27="",$E27=""),"",IF(SUMPRODUCT(('حجز الإجازات'!$B$5:$B$104=$B27)*('حجز الإجازات'!$G$5:$G$104<>"مرفوض")*('حجز الإجازات'!$D$5:$D$104<=$E27)*($D27<=('حجز الإجازات'!$E$5:$E$104)))-(($B27<>"")*($G27<>"مرفوض"))>0,"⚠ تعارض","✓ سليم")) | I27: =IF($D27="","",IF(SUMPRODUCT(('حجز الإجازات'!$G$5:$G$104<>"مرفوض")*('حجز الإجازات'!$D$5:$D$104<=$D27)*($D27<=('حجز الإجازات'!$E$5:$E$104)))>MaxLeave,"⚠ مجازين "&SUMPRODUCT(('حجز الإجازات'!$G$5:$G$104<>"مرفوض")*('حجز الإجازات'!$D$5:$D$104<=$D27)*($D27<=('حجز الإجازات'!$E$5:$E$104)))&" / الحد "&MaxLeave,"✓ مجازين "&SUMPRODUCT(('حجز الإجازات'!$G$5:$G$104<>"مرفوض")*('حجز الإجازات'!$D$5:$D$104<=$D27)*($D27<=('حجز الإجازات'!$E$5:$E$104)))&" / الحد "&MaxLeave))
A28: 24 | F28: =IF(OR($D28="",$E28=""),"",$E28-$D28+1-SUMPRODUCT((Holidays>=$D28)*(Holidays<=$E28))) | H28: =IF(OR($B28="",$D28="",$E28=""),"",IF(SUMPRODUCT(('حجز الإجازات'!$B$5:$B$104=$B28)*('حجز الإجازات'!$G$5:$G$104<>"مرفوض")*('حجز الإجازات'!$D$5:$D$104<=$E28)*($D28<=('حجز الإجازات'!$E$5:$E$104)))-(($B28<>"")*($G28<>"مرفوض"))>0,"⚠ تعارض","✓ سليم")) | I28: =IF($D28="","",IF(SUMPRODUCT(('حجز الإجازات'!$G$5:$G$104<>"مرفوض")*('حجز الإجازات'!$D$5:$D$104<=$D28)*($D28<=('حجز الإجازات'!$E$5:$E$104)))>MaxLeave,"⚠ مجازين "&SUMPRODUCT(('حجز الإجازات'!$G$5:$G$104<>"مرفوض")*('حجز الإجازات'!$D$5:$D$104<=$D28)*($D28<=('حجز الإجازات'!$E$5:$E$104)))&" / الحد "&MaxLeave,"✓ مجازين "&SUMPRODUCT(('حجز الإجازات'!$G$5:$G$104<>"مرفوض")*('حجز الإجازات'!$D$5:$D$104<=$D28)*($D28<=('حجز الإجازات'!$E$5:$E$104)))&" / الحد "&MaxLeave))
... A104: 100 | F104: =IF(OR($D104="",$E104=""),"",$E104-$D104+1-SUMPRODUCT((Holidays>=$D104)*(Holidays<=$E104))) | H104: =IF(OR($B104="",$D104="",$E104=""),"",IF(SUMPRODUCT(('حجز الإجازات'!$B$5:$B$104=$B104)*('حجز الإجازات'!$G$5:$G$104<>"مرفوض")*('حجز الإجازات'!$D$5:$D$104<=$E104)*($D104<=('حجز الإجازات'!$E$5:$E$104)))-(($B104<>"")*($G104<>"مرفوض"))>0,"⚠ تعارض","✓ سليم")) | I104: =IF($D104="","",IF(SUMPRODUCT(('حجز الإجازات'!$G$5:$G$104<>"مرفوض")*('حجز الإجازات'!$D$5:$D$104<=$D104)*($D104<=('حجز الإجازات'!$E$5:$E$104)))>MaxLeave,"⚠ مجازين "&SUMPRODUCT(('حجز الإجازات'!$G$5:$G$104<>"مرفوض")*('حجز الإجازات'!$D$5:$D$104<=$D104)*($D104<=('حجز الإجازات'!$E$5:$E$104)))&" / الحد "&MaxLeave,"✓ مجازين "&SUMPRODUCT(('حجز الإجازات'!$G$5:$G$104<>"مرفوض")*('حجز الإجازات'!$D$5:$D$104<=$D104)*($D104<=('حجز الإجازات'!$E$5:$E$104)))&" / الحد "&MaxLeave))

Sheet جدول الورديات
A1: جدول الورديات — 6 عمل / 4 راحة — صباح (6ص-1م) / عصر (1م-9م) / ليل (9م-6ص) | D1: يونيو 2026 | U1: يوليو 2026 | AZ1: أغسطس 2026 | CE1: سبتمبر 2026 | DI1: أكتوبر 2026 | EN1: نوفمبر 2026 | FR1: ديسمبر 2026 | GW1: يناير 2027 | IB1: فبراير 2027 | JD1: مارس 2027 | KI1: أبريل 2027 | LM1: مايو 2027 | MR1: يونيو 2027
B2: التاريخ ← | D2: الأحد | E2: الإثنين | F2: الثلاثاء | G2: الأربعاء | H2: الخميس | I2: الجمعة | J2: السبت | K2: الأحد | L2: الإثنين | M2: الثلاثاء | N2: الأربعاء | O2: الخميس | P2: الجمعة | Q2: السبت | R2: الأحد | S2: الإثنين | T2: الثلاثاء | U2: الأربعاء | V2: الخميس | W2: الجمعة | X2: السبت | Y2: الأحد | Z2: الإثنين | AA2: الثلاثاء | AB2: الأربعاء | AC2: الخميس | AD2: الجمعة | AE2: السبت | AF2: الأحد | AG2: الإثنين | AH2: الثلاثاء | AI2: الأربعاء | AJ2: الخميس | AK2: الجمعة | AL2: السبت | AM2: الأحد | AN2: الإثنين | AO2: الثلاثاء | AP2: الأربعاء | AQ2: الخميس | AR2: الجمعة | AS2: السبت | AT2: الأحد | AU2: الإثنين | AV2: الثلاثاء | AW2: الأربعاء | AX2: الخميس | AY2: الجمعة | AZ2: السبت | BA2: الأحد | BB2: الإثنين | BC2: الثلاثاء | BD2: الأربعاء | BE2: الخميس | BF2: الجمعة | BG2: السبت | BH2: الأحد | BI2: الإثنين | BJ2: الثلاثاء | BK2: الأربعاء | BL2: الخميس | BM2: الجمعة | BN2: السبت | BO2: الأحد | BP2: الإثنين | BQ2: الثلاثاء | BR2: الأربعاء | BS2: الخميس | BT2: الجمعة | BU2: السبت | BV2: الأحد | BW2: الإثنين | BX2: الثلاثاء | BY2: الأربعاء | BZ2: الخميس | CA2: الجمعة | CB2: السبت | CC2: الأحد | CD2: الإثنين | CE2: الثلاثاء | CF2: الأربعاء | CG2: الخميس | CH2: الجمعة | CI2: السبت | CJ2: الأحد | CK2: الإثنين | CL2: الثلاثاء | CM2: الأربعاء | CN2: الخميس | CO2: الجمعة | CP2: السبت | CQ2: الأحد | CR2: الإثنين | CS2: الثلاثاء | CT2: الأربعاء | CU2: الخميس | CV2: الجمعة | CW2: السبت | CX2: الأحد | CY2: الإثنين | CZ2: الثلاثاء | DA2: الأربعاء | DB2: الخميس | DC2: الجمعة | DD2: السبت | DE2: الأحد | DF2: الإثنين | DG2: الثلاثاء | DH2: الأربعاء | DI2: الخميس | DJ2: الجمعة | DK2: السبت | DL2: الأحد | DM2: الإثنين | DN2: الثلاثاء | DO2: الأربعاء | DP2: الخميس | DQ2: الجمعة | DR2: السبت | DS2: الأحد | DT2: الإثنين | DU2: الثلاثاء | DV2: الأربعاء | DW2: الخميس | DX2: الجمعة | DY2: السبت | DZ2: الأحد | EA2: الإثنين | EB2: الثلاثاء | EC2: الأربعاء | ED2: الخميس | EE2: الجمعة | EF2: السبت | EG2: الأحد | EH2: الإثنين | EI2: الثلاثاء | EJ2: الأربعاء | EK2: الخميس | EL2: الجمعة | EM2: السبت | EN2: الأحد | EO2: الإثنين | EP2: الثلاثاء | EQ2: الأربعاء | ER2: الخميس | ES2: الجمعة | ET2: السبت | EU2: الأحد | EV2: الإثنين | EW2: الثلاثاء | EX2: الأربعاء | EY2: الخميس | EZ2: الجمعة | FA2: السبت | FB2: الأحد | FC2: الإثنين | FD2: الثلاثاء | FE2: الأربعاء | FF2: الخميس | FG2: الجمعة | FH2: السبت | FI2: الأحد | FJ2: الإثنين | FK2: الثلاثاء | FL2: الأربعاء | FM2: الخميس | FN2: الجمعة | FO2: السبت | FP2: الأحد | FQ2: الإثنين | FR2: الثلاثاء | FS2: الأربعاء | FT2: الخميس | FU2: الجمعة | FV2: السبت | FW2: الأحد | FX2: الإثنين | FY2: الثلاثاء | FZ2: الأربعاء | GA2: الخميس | GB2: الجمعة | GC2: السبت | GD2: الأحد | GE2: الإثنين | GF2: الثلاثاء | GG2: الأربعاء | GH2: الخميس | GI2: الجمعة | GJ2: السبت | GK2: الأحد | GL2: الإثنين | GM2: الثلاثاء | GN2: الأربعاء | GO2: الخميس | GP2: الجمعة | GQ2: السبت | GR2: الأحد | GS2: الإثنين | GT2: الثلاثاء | GU2: الأربعاء | GV2: الخميس | GW2: الجمعة | GX2: السبت | GY2: الأحد | GZ2: الإثنين | HA2: الثلاثاء | HB2: الأربعاء | HC2: الخميس | HD2: الجمعة | HE2: السبت | HF2: الأحد | HG2: الإثنين | HH2: الثلاثاء | HI2: الأربعاء | HJ2: الخميس | HK2: الجمعة | HL2: السبت | HM2: الأحد | HN2: الإثنين | HO2: الثلاثاء | HP2: الأربعاء | HQ2: الخميس | HR2: الجمعة | HS2: السبت | HT2: الأحد | HU2: الإثنين | HV2: الثلاثاء | HW2: الأربعاء | HX2: الخميس | HY2: الجمعة | HZ2: السبت | IA2: الأحد | IB2: الإثنين | IC2: الثلاثاء | ID2: الأربعاء | IE2: الخميس | IF2: الجمعة | IG2: السبت | IH2: الأحد | II2: الإثنين | IJ2: الثلاثاء | IK2: الأربعاء | IL2: الخميس | IM2: الجمعة | IN2: السبت | IO2: الأحد | IP2: الإثنين | IQ2: الثلاثاء | IR2: الأربعاء | IS2: الخميس | IT2: الجمعة | IU2: السبت | IV2: الأحد | IW2: الإثنين | IX2: الثلاثاء | IY2: الأربعاء | IZ2: الخميس | JA2: الجمعة | JB2: السبت | JC2: الأحد | JD2: الإثنين | JE2: الثلاثاء | JF2: الأربعاء | JG2: الخميس | JH2: الجمعة | JI2: السبت | JJ2: الأحد | JK2: الإثنين | JL2: الثلاثاء | JM2: الأربعاء | JN2: الخميس | JO2: الجمعة | JP2: السبت | JQ2: الأحد | JR2: الإثنين | JS2: الثلاثاء | JT2: الأربعاء | JU2: الخميس | JV2: الجمعة | JW2: السبت | JX2: الأحد | JY2: الإثنين | JZ2: الثلاثاء | KA2: الأربعاء | KB2: الخميس | KC2: الجمعة | KD2: السبت | KE2: الأحد | KF2: الإثنين | KG2: الثلاثاء | KH2: الأربعاء | KI2: الخميس | KJ2: الجمعة | KK2: السبت | KL2: الأحد | KM2: الإثنين | KN2: الثلاثاء | KO2: الأربعاء | KP2: الخميس | KQ2: الجمعة | KR2: السبت | KS2: الأحد | KT2: الإثنين | KU2: الثلاثاء | KV2: الأربعاء | KW2: الخميس | KX2: الجمعة | KY2: السبت | KZ2: الأحد | LA2: الإثنين | LB2: الثلاثاء | LC2: الأربعاء | LD2: الخميس | LE2: الجمعة | LF2: السبت | LG2: الأحد | LH2: الإثنين | LI2: الثلاثاء | LJ2: الأربعاء | LK2: الخميس | LL2: الجمعة | LM2: السبت | LN2: الأحد | LO2: الإثنين | LP2: الثلاثاء | LQ2: الأربعاء | LR2: الخميس | LS2: الجمعة | LT2: السبت | LU2: الأحد | LV2: الإثنين | LW2: الثلاثاء | LX2: الأربعاء | LY2: الخميس | LZ2: الجمعة | MA2: السبت | MB2: الأحد | MC2: الإثنين | MD2: الثلاثاء | ME2: الأربعاء | MF2: الخميس | MG2: الجمعة | MH2: السبت | MI2: الأحد | MJ2: الإثنين | MK2: الثلاثاء | ML2: الأربعاء | MM2: الخميس | MN2: الجمعة | MO2: السبت | MP2: الأحد | MQ2: الإثنين | MR2: الثلاثاء | MS2: الأربعاء | MT2: الخميس | MU2: الجمعة | MV2: السبت | MW2: الأحد | MX2: الإثنين | MY2: الثلاثاء | MZ2: الأربعاء | NA2: الخميس | NB2: الجمعة | NC2: السبت | ND2: الأحد
A3: م | B3: الاسم | C3: الرقم الوظيفي | D3: 46187 | E3: 46188 | F3: 46189 | G3: 46190 | H3: 46191 | I3: 46192 | J3: 46193 | K3: 46194 | L3: 46195 | M3: 46196 | N3: 46197 | O3: 46198 | P3: 46199 | Q3: 46200 | R3: 46201 | S3: 46202 | T3: 46203 | U3: 46204 | V3: 46205 | W3: 46206 | X3: 46207 | Y3: 46208 | Z3: 46209 | AA3: 46210 | AB3: 46211 | AC3: 46212 | AD3: 46213 | AE3: 46214 | AF3: 46215 | AG3: 46216 | AH3: 46217 | AI3: 46218 | AJ3: 46219 | AK3: 46220 | AL3: 46221 | AM3: 46222 | AN3: 46223 | AO3: 46224 | AP3: 46225 | AQ3: 46226 | AR3: 46227 | AS3: 46228 | AT3: 46229 | AU3: 46230 | AV3: 46231 | AW3: 46232 | AX3: 46233 | AY3: 46234 | AZ3: 46235 | BA3: 46236 | BB3: 46237 | BC3: 46238 | BD3: 46239 | BE3: 46240 | BF3: 46241 | BG3: 46242 | BH3: 46243 | BI3: 46244 | BJ3: 46245 | BK3: 46246 | BL3: 46247 | BM3: 46248 | BN3: 46249 | BO3: 46250 | BP3: 46251 | BQ3: 46252 | BR3: 46253 | BS3: 46254 | BT3: 46255 | BU3: 46256 | BV3: 46257 | BW3: 46258 | BX3: 46259 | BY3: 46260 | BZ3: 46261 | CA3: 46262 | CB3: 46263 | CC3: 46264 | CD3: 46265 | CE3: 46266 | CF3: 46267 | CG3: 46268 | CH3: 46269 | CI3: 46270 | CJ3: 46271 | CK3: 46272 | CL3: 46273 | CM3: 46274 | CN3: 46275 | CO3: 46276 | CP3: 46277 | CQ3: 46278 | CR3: 46279 | CS3: 46280 | CT3: 46281 | CU3: 46282 | CV3: 46283 | CW3: 46284 | CX3: 46285 | CY3: 46286 | CZ3: 46287 | DA3: 46288 | DB3: 46289 | DC3: 46290 | DD3: 46291 | DE3: 46292 | DF3: 46293 | DG3: 46294 | DH3: 46295 | DI3: 46296 | DJ3: 46297 | DK3: 46298 | DL3: 46299 | DM3: 46300 | DN3: 46301 | DO3: 46302 | DP3: 46303 | DQ3: 46304 | DR3: 46305 | DS3: 46306 | DT3: 46307 | DU3: 46308 | DV3: 46309 | DW3: 46310 | DX3: 46311 | DY3: 46312 | DZ3: 46313 | EA3: 46314 | EB3: 46315 | EC3: 46316 | ED3: 46317 | EE3: 46318 | EF3: 46319 | EG3: 46320 | EH3: 46321 | EI3: 46322 | EJ3: 46323 | EK3: 46324 | EL3: 46325 | EM3: 46326 | EN3: 46327 | EO3: 46328 | EP3: 46329 | EQ3: 46330 | ER3: 46331 | ES3: 46332 | ET3: 46333 | EU3: 46334 | EV3: 46335 | EW3: 46336 | EX3: 46337 | EY3: 46338 | EZ3: 46339 | FA3: 46340 | FB3: 46341 | FC3: 46342 | FD3: 46343 | FE3: 46344 | FF3: 46345 | FG3: 46346 | FH3: 46347 | FI3: 46348 | FJ3: 46349 | FK3: 46350 | FL3: 46351 | FM3: 46352 | FN3: 46353 | FO3: 46354 | FP3: 46355 | FQ3: 46356 | FR3: 46357 | FS3: 46358 | FT3: 46359 | FU3: 46360 | FV3: 46361 | FW3: 46362 | FX3: 46363 | FY3: 46364 | FZ3: 46365 | GA3: 46366 | GB3: 46367 | GC3: 46368 | GD3: 46369 | GE3: 46370 | GF3: 46371 | GG3: 46372 | GH3: 46373 | GI3: 46374 | GJ3: 46375 | GK3: 46376 | GL3: 46377 | GM3: 46378 | GN3: 46379 | GO3: 46380 | GP3: 46381 | GQ3: 46382 | GR3: 46383 | GS3: 46384 | GT3: 46385 | GU3: 46386 | GV3: 46387 | GW3: 46388 | GX3: 46389 | GY3: 46390 | GZ3: 46391 | HA3: 46392 | HB3: 46393 | HC3: 46394 | HD3: 46395 | HE3: 46396 | HF3: 46397 | HG3: 46398 | HH3: 46399 | HI3: 46400 | HJ3: 46401 | HK3: 46402 | HL3: 46403 | HM3: 46404 | HN3: 46405 | HO3: 46406 | HP3: 46407 | HQ3: 46408 | HR3: 46409 | HS3: 46410 | HT3: 46411 | HU3: 46412 | HV3: 46413 | HW3: 46414 | HX3: 46415 | HY3: 46416 | HZ3: 46417 | IA3: 46418 | IB3: 46419 | IC3: 46420 | ID3: 46421 | IE3: 46422 | IF3: 46423 | IG3: 46424 | IH3: 46425 | II3: 46426 | IJ3: 46427 | IK3: 46428 | IL3: 46429 | IM3: 46430 | IN3: 46431 | IO3: 46432 | IP3: 46433 | IQ3: 46434 | IR3: 46435 | IS3: 46436 | IT3: 46437 | IU3: 46438 | IV3: 46439 | IW3: 46440 | IX3: 46441 | IY3: 46442 | IZ3: 46443 | JA3: 46444 | JB3: 46445 | JC3: 46446 | JD3: 46447 | JE3: 46448 | JF3: 46449 | JG3: 46450 | JH3: 46451 | JI3: 46452 | JJ3: 46453 | JK3: 46454 | JL3: 46455 | JM3: 46456 | JN3: 46457 | JO3: 46458 | JP3: 46459 | JQ3: 46460 | JR3: 46461 | JS3: 46462 | JT3: 46463 | JU3: 46464 | JV3: 46465 | JW3: 46466 | JX3: 46467 | JY3: 46468 | JZ3: 46469 | KA3: 46470 | KB3: 46471 | KC3: 46472 | KD3: 46473 | KE3: 46474 | KF3: 46475 | KG3: 46476 | KH3: 46477 | KI3: 46478 | KJ3: 46479 | KK3: 46480 | KL3: 46481 | KM3: 46482 | KN3: 46483 | KO3: 46484 | KP3: 46485 | KQ3: 46486 | KR3: 46487 | KS3: 46488 | KT3: 46489 | KU3: 46490 | KV3: 46491 | KW3: 46492 | KX3: 46493 | KY3: 46494 | KZ3: 46495 | LA3: 46496 | LB3: 46497 | LC3: 46498 | LD3: 46499 | LE3: 46500 | LF3: 46501 | LG3: 46502 | LH3: 46503 | LI3: 46504 | LJ3: 46505 | LK3: 46506 | LL3: 46507 | LM3: 46508 | LN3: 46509 | LO3: 46510 | LP3: 46511 | LQ3: 46512 | LR3: 46513 | LS3: 46514 | LT3: 46515 | LU3: 46516 | LV3: 46517 | LW3: 46518 | LX3: 46519 | LY3: 46520 | LZ3: 46521 | MA3: 46522 | MB3: 46523 | MC3: 46524 | MD3: 46525 | ME3: 46526 | MF3: 46527 | MG3: 46528 | MH3: 46529 | MI3: 46530 | MJ3: 46531 | MK3: 46532 | ML3: 46533 | MM3: 46534 | MN3: 46535 | MO3: 46536 | MP3: 46537 | MQ3: 46538 | MR3: 46539 | MS3: 46540 | MT3: 46541 | MU3: 46542 | MV3: 46543 | MW3: 46544 | MX3: 46545 | MY3: 46546 | MZ3: 46547 | NA3: 46548 | NB3: 46549 | NC3: 46550 | ND3: 46551
A4: 1 | B4: ='الموظفون'!B2 | C4: ='الموظفون'!C2 | D4: =IF(SUMPRODUCT(('حجز الإجازات'!$B$5:$B$104='الموظفون'!$B$2)*('حجز الإجازات'!$D$5:$D$104<=D$3)*(('حجز الإجازات'!$E$5:$E$104)>=D$3)*('حجز الإجازات'!$G$5:$G$104="معتمد")*ROW('حجز الإجازات'!$B$5:$B$104))=0,IF(D$3<'الموظفون'!$D$2,"",IF(ISNUMBER(MATCH(D$3,Holidays,0)),"عطلة",IF(MOD(D$3-'الموظفون'!$D$2,CycleWork+CycleRest)<CycleWork,INDEX('الإعدادات والقوائم'!$H$2:$H$4,MOD(INT(MOD(D$3-'الموظفون'!$D$2,CycleWork+CycleRest)*3/CycleWork)+MATCH(StartShift,'الإعدادات والقوائم'!$H$2:$H$4,0)-1,3)+1),"راحة"))),INDEX('حجز الإجازات'!$C$5:$C$104,(SUMPRODUCT(('حجز الإجازات'!$B$5:$B$104='الموظفون'!$B$2)*('حجز الإجازات'!$D$5:$D$104<=D$3)*(('حجز الإجازات'!$E$5:$E$104)>=D$3)*('حجز الإجازات'!$G$5:$G$104="معتمد")*ROW('حجز الإجازات'!$B$5:$B$104)))-5+1)) | E4: =IF(SUMPRODUCT(('حجز الإجازات'!$B$5:$B$104='الموظفون'!$B$2)*('حجز الإجازات'!$D$5:$D$104<=E$3)*(('حجز الإجازات'!$E$5:$E$104)>=E$3)*('حجز الإجازات'!$G$5:$G$104="معتمد")*ROW('حجز الإجازات'!$B$5:$B$104))=0,IF(E$3<'الموظفون'!$D$2,"",IF(ISNUMBER(MATCH(E$3,Holidays,0)),"عطلة",IF(MOD(E$3-'الموظفون'!$D$2,CycleWork+CycleRest)<CycleWork,INDEX('الإعدادات والقوائم'!$H$2:$H$4,MOD(INT(MOD(E$3-'الموظفون'!$D$2,CycleWork+CycleRest)*3/CycleWork)+MATCH(StartShift,'الإعدادات والقوائم'!$H$2:$H$4,0)-1,3)+1),"راحة"))),INDEX('حجز الإجازات'!$C$5:$C$104,(SUMPRODUCT(('حجز الإجازات'!$B$5:$B$104='الموظفون'!$B$2)*('حجز الإجازات'!$D$5:$D$104<=E$3)*(('حجز الإجازات'!$E$5:$E$104)>=E$3)*('حجز الإجازات'!$G$5:$G$104="معتمد")*ROW('حجز الإجازات'!$B$5:$B$104)))-5+1)) | F4: =IF(SUMPRODUCT(('حجز الإجازات'!$B$5:$B$104='الموظفون'!$B$2)*('حجز الإجازات'!$D$5:$D$104<=F$3)*(('حجز الإجازات'!$E$5:$E$104)>=F$3)*('حجز الإجازات'!$G$5:$G$104="معتمد")*ROW('حجز الإجازات'!$B$5:$B$104))=0,IF(F$3<'الموظفون'!$D$2,"",IF(ISNUMBER(MATCH(F$3,Holidays,0)),"عطلة",IF(MOD(F$3-'الموظفون'!$D$2,CycleWork+CycleRest)<CycleWork,INDEX('الإعدادات والقوائم'!$H$2:$H$4,MOD(INT(MOD(F$3-'الموظفون'!$D$2,CycleWork+CycleRest)*3/CycleWork)+MATCH(StartShift,'الإعدادات والقوائم'!$H$2:$H$4,0)-1,3)+1),"راحة"))),INDEX('حجز الإجازات'!$C$5:$C$104,(SUMPRODUCT(('حجز الإجازات'!$B$5:$B$104='الموظفون'!$B$2)*('حجز الإجازات'!$D$5:$D$104<=F$3)*(('حجز الإجازات'!$E$5:$E$104)>=F$3)*('حجز الإجازات'!$G$5:$G$104="معتمد")*ROW('حجز الإجازات'!$B$5:$B$104)))-5+1)) | G4: =IF(SUMPRODUCT(('حجز الإجازات'!$B$5:$B$104='الموظفون'!$B$2)*('حجز الإجازات'!$D$5:$D$104<=G$3)*(('حجز الإجازات'!$E$5:$E$104)>=G$3)*('حجز الإجازات'!$G$5:$G$104="معتمد")*ROW('حجز الإجازات'!$B$5:$B$104))=0,IF(G$3<'الموظفون'!$D$2,"",IF(ISNUMBER(MATCH(G$3,Holidays,0)),"عطلة",IF(MOD(G$3-'الموظفون'!$D$2,CycleWork+CycleRest)<CycleWork,INDEX('الإعدادات والقوائم'!$H$2:$H$4,MOD(INT(MOD(G$3-'الموظفون'!$D$2,CycleWork+CycleRest)*3/CycleWork)+MATCH(StartShift,'الإعدادات والقوائم'!$H$2:$H$4,0)-1,3)+1),"راحة"))),INDEX('حجز الإجازات'!$C$5:$C$104,(SUMPRODUCT(('حجز الإجازات'!$B$5:$B$104='الموظفون'!$B$2)*('حجز الإجازات'!$D$5:$D$104<=G$3)*(('حجز الإجازات'!$E$5:$E$104)>=G$3)*('حجز الإجازات'!$G$5:$G$104="معتمد")*ROW('حجز الإجازات'!$B$5:$B$104)))-5+1)) | H4: =IF(SUMPRODUCT(('حجز الإجازات'!$B$5:$B$104='الموظفون'!$B$2)*('حجز الإجازات'!$D$5:$D$104<=H$3)*(('حجز الإجازات'!$E$5:$E$104)>=H$3)*('حجز الإجازات'!$G$5:$G$104="معتمد")*ROW('حجز الإجازات'!$B$5:$B$104))=0,IF(H$3<'الموظفون'!$D$2,"",IF(ISNUMBER(MATCH(H$3,Holidays,0)),"عطلة",IF(MOD(H$3-'الموظفون'!$D$2,CycleWork+CycleRest)<CycleWork,INDEX('الإعدادات والقوائم'!$H$2:$H$4,MOD(INT(MOD(H$3-'الموظفون'!$D$2,CycleWork+CycleRest)*3/CycleWork)+MATCH(StartShift,'الإعدادات والقوائم'!$H$2:$H$4,0)-1,3)+1),"راحة"))),INDEX('حجز الإجازات'!$C$5:$C$104,(SUMPRODUCT(('حجز الإجازات'!$B$5:$B$104='الموظفون'!$B$2)*('حجز الإجازات'!$D$5:$D$104<=H$3)*(('حجز الإجازات'!$E$5:$E$104)>=H$3)*('حجز الإجازات'!$G$5:$G$104="معتمد")*ROW('حجز الإجازات'!$B$5:$B$104)))-5+1)) | I4: =IF(SUMPRODUCT(('حجز الإجازات'!$B$5:$B$104='الموظفون'!$B$2)*('حجز الإجازات'!$D$5:$D$104<=I$3)*(('حجز الإجازات'!$E$5:$E$104)>=I$3)*('حجز الإجازات'!$G$5:$G$104="معتمد")*ROW('حجز الإجازات'!$B$5:$B$104))=0,IF(I$3<'الموظفون'!$D$2,"",IF(ISNUMBER(MATCH(I$3,Holidays,0)),"عطلة",IF(MOD(I$3-'الموظفون'!$D$2,CycleWork+CycleRest)<CycleWork,INDEX('الإعدادات والقوائم'!$H$2:$H$4,MOD(INT(MOD(I$3-'الموظفون'!$D$2,CycleWork+CycleRest)*3/CycleWork)+MATCH(StartShift,'الإعدادات والقوائم'!$H$2:$H$4,0)-1,3)+1),"راحة"))),INDEX('حجز الإجازات'!$C$5:$C$104,(SUMPRODUCT(('حجز الإجازات'!$B$5:$B$104='الموظفون'!$B$2)*('حجز الإجازات'!$D$5:$D$104<=I$3)*(('حجز الإجازات'!$E$5:$E$104)>=I$3)*('حجز الإجازات'!$G$5:$G$104="معتمد")*ROW('حجز الإجازات'!$B$5:$B$104)))-5+1)) | J4: =IF(SUMPRODUCT(('حجز الإجازات'!$B$5:$B$104='الموظفون'!$B$2)*('حجز الإجازات'!$D$5:$D$104<=J$3)*(('حجز الإجازات'!$E$5:$E$104)>=J$3)*('حجز الإجازات'!$G$5:$G$104="معتمد")*ROW('حجز الإجازات'!$B$5:$B$104))=0,IF(J$3<'الموظفون'!$D$2,"",IF(ISNUMBER(MATCH(J$3,Holidays,0)),"عطلة",IF(MOD(J$3-'الموظفون'!$D$2,CycleWork+CycleRest)<CycleWork,INDEX('الإعدادات والقوائم'!$H$2:$H$4,MOD(INT(MOD(J$3-'الموظفون'!$D$2,CycleWork+CycleRest)*3/CycleWork)+MATCH(StartShift,'الإعدادات والقوائم'!$H$2:$H$4,0)-1,3)+1),"راحة"))),INDEX('حجز الإجازات'!$C$5:$C$104,(SUMPRODUCT(('حجز الإجازات'!$B$5:$B$104='الموظفون'!$B$2)*('حجز الإجازات'!$D$5:$D$104<=J$3)*(('حجز الإجازات'!$E$5:$E$104)>=J$3)*('حجز الإجازات'!$G$5:$G$104="معتمد")*ROW('حجز الإجازات'!$B$5:$B$104)))-5+1)) | K4: =IF(SUMPRODUCT(('حجز الإجازات'!$B$5:$B$104='الموظفون'!$B$2)*('حجز الإجازات'!$D$5:$D$104<=K$3)*(('حجز الإجازات'!$E$5:$E$104)>=K$3)*('حجز الإجازات'!$G$5:$G$104="معتمد")*ROW('حجز الإجازات'!$B$5:$B$104))=0,IF(K$3<'الموظفون'!$D$2,"",IF(ISNUMBER(MATCH(K$3,Holidays,0)),"عطلة",IF(MOD(K$3-'الموظفون'!$D$2,CycleWork+CycleRest)<CycleWork,INDEX('الإعدادات والقوائم'!$H$2:$H$4,MOD(INT(MOD(K$3-'الموظفون'!$D$2,CycleWork+CycleRest)*3/CycleWork)+MATCH(StartShift,'الإعدادات والقوائم'!$H$2:$H$4,0)-1,3)+1),"راحة"))),INDEX('حجز الإجازات'!$C$5:$C$104,(SUMPRODUCT(('حجز الإجازات'!$B$5:$B$104='الموظفون'!$B$2)*('حجز الإجازات'!$D$5:$D$104<=K$3)*(('حجز الإجازات'!$E$5:$E$104)>=K$3)*('حجز الإجازات'!$G$5:$G$104="معتمد")*ROW('حجز الإجازات'!$B$5:$B$104)))-5+1)) | ... ND4: =IF(SUMPRODUCT(('حجز الإجازات'!$B$5:$B$104='الموظفون'!$B$2)*('حجز الإجازات'!$D$5:$D$104<=ND$3)*(('حجز الإجازات'!$E$5:$E$104)>=ND$3)*('حجز الإجازات'!$G$5:$G$104="معتمد")*ROW('حجز الإجازات'!$B$5:$B$104))=0,IF(ND$3<'الموظفون'!$D$2,"",IF(ISNUMBER(MATCH(ND$3,Holidays,0)),"عطلة",IF(MOD(ND$3-'الموظفون'!$D$2,CycleWork+CycleRest)<CycleWork,INDEX('الإعدادات والقوائم'!$H$2:$H$4,MOD(INT(MOD(ND$3-'الموظفون'!$D$2,CycleWork+CycleRest)*3/CycleWork)+MATCH(StartShift,'الإعدادات والقوائم'!$H$2:$H$4,0)-1,3)+1),"راحة"))),INDEX('حجز الإجازات'!$C$5:$C$104,(SUMPRODUCT(('حجز الإجازات'!$B$5:$B$104='الموظفون'!$B$2)*('حجز الإجازات'!$D$5:$D$104<=ND$3)*(('حجز الإجازات'!$E$5:$E$104)>=ND$3)*('حجز الإجازات'!$G$5:$G$104="معتمد")*ROW('حجز الإجازات'!$B$5:$B$104)))-5+1))
A5: 2 | B5: ='الموظفون'!B3 | C5: ='الموظفون'!C3 | D5: =IF(SUMPRODUCT(('حجز الإجازات'!$B$5:$B$104='الموظفون'!$B$3)*('حجز الإجازات'!$D$5:$D$104<=D$3)*(('حجز الإجازات'!$E$5:$E$104)>=D$3)*('حجز الإجازات'!$G$5:$G$104="معتمد")*ROW('حجز الإجازات'!$B$5:$B$104))=0,IF(D$3<'الموظفون'!$D$3,"",IF(ISNUMBER(MATCH(D$3,Holidays,0)),"عطلة",IF(MOD(D$3-'الموظفون'!$D$3,CycleWork+CycleRest)<CycleWork,INDEX('الإعدادات والقوائم'!$H$2:$H$4,MOD(INT(MOD(D$3-'الموظفون'!$D$3,CycleWork+CycleRest)*3/CycleWork)+MATCH(StartShift,'الإعدادات والقوائم'!$H$2:$H$4,0)-1,3)+1),"راحة"))),INDEX('حجز الإجازات'!$C$5:$C$104,(SUMPRODUCT(('حجز الإجازات'!$B$5:$B$104='الموظفون'!$B$3)*('حجز الإجازات'!$D$5:$D$104<=D$3)*(('حجز الإجازات'!$E$5:$E$104)>=D$3)*('حجز الإجازات'!$G$5:$G$104="معتمد")*ROW('حجز الإجازات'!$B$5:$B$104)))-5+1)) | E5: =IF(SUMPRODUCT(('حجز الإجازات'!$B$5:$B$104='الموظفون'!$B$3)*('حجز الإجازات'!$D$5:$D$104<=E$3)*(('حجز الإجازات'!$E$5:$E$104)>=E$3)*('حجز الإجازات'!$G$5:$G$104="معتمد")*ROW('حجز الإجازات'!$B$5:$B$104))=0,IF(E$3<'الموظفون'!$D$3,"",IF(ISNUMBER(MATCH(E$3,Holidays,0)),"عطلة",IF(MOD(E$3-'الموظفون'!$D$3,CycleWork+CycleRest)<CycleWork,INDEX('الإعدادات والقوائم'!$H$2:$H$4,MOD(INT(MOD(E$3-'الموظفون'!$D$3,CycleWork+CycleRest)*3/CycleWork)+MATCH(StartShift,'الإعدادات والقوائم'!$H$2:$H$4,0)-1,3)+1),"راحة"))),INDEX('حجز الإجازات'!$C$5:$C$104,(SUMPRODUCT(('حجز الإجازات'!$B$5:$B$104='الموظفون'!$B$3)*('حجز الإجازات'!$D$5:$D$104<=E$3)*(('حجز الإجازات'!$E$5:$E$104)>=E$3)*('حجز الإجازات'!$G$5:$G$104="معتمد")*ROW('حجز الإجازات'!$B$5:$B$104)))-5+1)) | F5: =IF(SUMPRODUCT(('حجز الإجازات'!$B$5:$B$104='الموظفون'!$B$3)*('حجز الإجازات'!$D$5:$D$104<=F$3)*(('حجز الإجازات'!$E$5:$E$104)>=F$3)*('حجز الإجازات'!$G$5:$G$104="معتمد")*ROW('حجز الإجازات'!$B$5:$B$104))=0,IF(F$3<'الموظفون'!$D$3,"",IF(ISNUMBER(MATCH(F$3,Holidays,0)),"عطلة",IF(MOD(F$3-'الموظفون'!$D$3,CycleWork+CycleRest)<CycleWork,INDEX('الإعدادات والقوائم'!$H$2:$H$4,MOD(INT(MOD(F$3-'الموظفون'!$D$3,CycleWork+CycleRest)*3/CycleWork)+MATCH(StartShift,'الإعدادات والقوائم'!$H$2:$H$4,0)-1,3)+1),"راحة"))),INDEX('حجز الإجازات'!$C$5:$C$104,(SUMPRODUCT(('حجز الإجازات'!$B$5:$B$104='الموظفون'!$B$3)*('حجز الإجازات'!$D$5:$D$104<=F$3)*(('حجز الإجازات'!$E$5:$E$104)>=F$3)*('حجز الإجازات'!$G$5:$G$104="معتمد")*ROW('حجز الإجازات'!$B$5:$B$104)))-5+1)) | G5: =IF(SUMPRODUCT(('حجز الإجازات'!$B$5:$B$104='الموظفون'!$B$3)*('حجز الإجازات'!$D$5:$D$104<=G$3)*(('حجز الإجازات'!$E$5:$E$104)>=G$3)*('حجز الإجازات'!$G$5:$G$104="معتمد")*ROW('حجز الإجازات'!$B$5:$B$104))=0,IF(G$3<'الموظفون'!$D$3,"",IF(ISNUMBER(MATCH(G$3,Holidays,0)),"عطلة",IF(MOD(G$3-'الموظفون'!$D$3,CycleWork+CycleRest)<CycleWork,INDEX('الإعدادات والقوائم'!$H$2:$H$4,MOD(INT(MOD(G$3-'الموظفون'!$D$3,CycleWork+CycleRest)*3/CycleWork)+MATCH(StartShift,'الإعدادات والقوائم'!$H$2:$H$4,0)-1,3)+1),"راحة"))),INDEX('حجز الإجازات'!$C$5:$C$104,(SUMPRODUCT(('حجز الإجازات'!$B$5:$B$104='الموظفون'!$B$3)*('حجز الإجازات'!$D$5:$D$104<=G$3)*(('حجز الإجازات'!$E$5:$E$104)>=G$3)*('حجز الإجازات'!$G$5:$G$104="معتمد")*ROW('حجز الإجازات'!$B$5:$B$104)))-5+1)) | H5: =IF(SUMPRODUCT(('حجز الإجازات'!$B$5:$B$104='الموظفون'!$B$3)*('حجز الإجازات'!$D$5:$D$104<=H$3)*(('حجز الإجازات'!$E$5:$E$104)>=H$3)*('حجز الإجازات'!$G$5:$G$104="معتمد")*ROW('حجز الإجازات'!$B$5:$B$104))=0,IF(H$3<'الموظفون'!$D$3,"",IF(ISNUMBER(MATCH(H$3,Holidays,0)),"عطلة",IF(MOD(H$3-'الموظفون'!$D$3,CycleWork+CycleRest)<CycleWork,INDEX('الإعدادات والقوائم'!$H$2:$H$4,MOD(INT(MOD(H$3-'الموظفون'!$D$3,CycleWork+CycleRest)*3/CycleWork)+MATCH(StartShift,'الإعدادات والقوائم'!$H$2:$H$4,0)-1,3)+1),"راحة"))),INDEX('حجز الإجازات'!$C$5:$C$104,(SUMPRODUCT(('حجز الإجازات'!$B$5:$B$104='الموظفون'!$B$3)*('حجز الإجازات'!$D$5:$D$104<=H$3)*(('حجز الإجازات'!$E$5:$E$104)>=H$3)*('حجز الإجازات'!$G$5:$G$104="معتمد")*ROW('حجز الإجازات'!$B$5:$B$104)))-5+1)) | I5: =IF(SUMPRODUCT(('حجز الإجازات'!$B$5:$B$104='الموظفون'!$B$3)*('حجز الإجازات'!$D$5:$D$104<=I$3)*(('حجز الإجازات'!$E$5:$E$104)>=I$3)*('حجز الإجازات'!$G$5:$G$104="معتمد")*ROW('حجز الإجازات'!$B$5:$B$104))=0,IF(I$3<'الموظفون'!$D$3,"",IF(ISNUMBER(MATCH(I$3,Holidays,0)),"عطلة",IF(MOD(I$3-'الموظفون'!$D$3,CycleWork+CycleRest)<CycleWork,INDEX('الإعدادات والقوائم'!$H$2:$H$4,MOD(INT(MOD(I$3-'الموظفون'!$D$3,CycleWork+CycleRest)*3/CycleWork)+MATCH(StartShift,'الإعدادات والقوائم'!$H$2:$H$4,0)-1,3)+1),"راحة"))),INDEX('حجز الإجازات'!$C$5:$C$104,(SUMPRODUCT(('حجز الإجازات'!$B$5:$B$104='الموظفون'!$B$3)*('حجز الإجازات'!$D$5:$D$104<=I$3)*(('حجز الإجازات'!$E$5:$E$104)>=I$3)*('حجز الإجازات'!$G$5:$G$104="معتمد")*ROW('حجز الإجازات'!$B$5:$B$104)))-5+1)) | J5: =IF(SUMPRODUCT(('حجز الإجازات'!$B$5:$B$104='الموظفون'!$B$3)*('حجز الإجازات'!$D$5:$D$104<=J$3)*(('حجز الإجازات'!$E$5:$E$104)>=J$3)*('حجز الإجازات'!$G$5:$G$104="معتمد")*ROW('حجز الإجازات'!$B$5:$B$104))=0,IF(J$3<'الموظفون'!$D$3,"",IF(ISNUMBER(MATCH(J$3,Holidays,0)),"عطلة",IF(MOD(J$3-'الموظفون'!$D$3,CycleWork+CycleRest)<CycleWork,INDEX('الإعدادات والقوائم'!$H$2:$H$4,MOD(INT(MOD(J$3-'الموظفون'!$D$3,CycleWork+CycleRest)*3/CycleWork)+MATCH(StartShift,'الإعدادات والقوائم'!$H$2:$H$4,0)-1,3)+1),"راحة"))),INDEX('حجز الإجازات'!$C$5:$C$104,(SUMPRODUCT(('حجز الإجازات'!$B$5:$B$104='الموظفون'!$B$3)*('حجز الإجازات'!$D$5:$D$104<=J$3)*(('حجز الإجازات'!$E$5:$E$104)>=J$3)*('حجز الإجازات'!$G$5:$G$104="معتمد")*ROW('حجز الإجازات'!$B$5:$B$104)))-5+1)) | K5: =IF(SUMPRODUCT(('حجز الإجازات'!$B$5:$B$104='الموظفون'!$B$3)*('حجز الإجازات'!$D$5:$D$104<=K$3)*(('حجز الإجازات'!$E$5:$E$104)>=K$3)*('حجز الإجازات'!$G$5:$G$104="معتمد")*ROW('حجز الإجازات'!$B$5:$B$104))=0,IF(K$3<'الموظفون'!$D$3,"",IF(ISNUMBER(MATCH(K$3,Holidays,0)),"عطلة",IF(MOD(K$3-'الموظفون'!$D$3,CycleWork+CycleRest)<CycleWork,INDEX('الإعدادات والقوائم'!$H$2:$H$4,MOD(INT(MOD(K$3-'الموظفون'!$D$3,CycleWork+CycleRest)*3/CycleWork)+MATCH(StartShift,'الإعدادات والقوائم'!$H$2:$H$4,0)-1,3)+1),"راحة"))),INDEX('حجز الإجازات'!$C$5:$C$104,(SUMPRODUCT(('حجز الإجازات'!$B$5:$B$104='الموظفون'!$B$3)*('حجز الإجازات'!$D$5:$D$104<=K$3)*(('حجز الإجازات'!$E$5:$E$104)>=K$3)*('حجز الإجازات'!$G$5:$G$104="معتمد")*ROW('حجز الإجازات'!$B$5:$B$104)))-5+1)) | ... ND5: =IF(SUMPRODUCT(('حجز الإجازات'!$B$5:$B$104='الموظفون'!$B$3)*('حجز الإجازات'!$D$5:$D$104<=ND$3)*(('حجز الإجازات'!$E$5:$E$104)>=ND$3)*('حجز الإجازات'!$G$5:$G$104="معتمد")*ROW('حجز الإجازات'!$B$5:$B$104))=0,IF(ND$3<'الموظفون'!$D$3,"",IF(ISNUMBER(MATCH(ND$3,Holidays,0)),"عطلة",IF(MOD(ND$3-'الموظفون'!$D$3,CycleWork+CycleRest)<CycleWork,INDEX('الإعدادات والقوائم'!$H$2:$H$4,MOD(INT(MOD(ND$3-'الموظفون'!$D$3,CycleWork+CycleRest)*3/CycleWork)+MATCH(StartShift,'الإعدادات والقوائم'!$H$2:$H$4,0)-1,3)+1),"راحة"))),INDEX('حجز الإجازات'!$C$5:$C$104,(SUMPRODUCT(('حجز الإجازات'!$B$5:$B$104='الموظفون'!$B$3)*('حجز الإجازات'!$D$5:$D$104<=ND$3)*(('حجز الإجازات'!$E$5:$E$104)>=ND$3)*('حجز الإجازات'!$G$5:$G$104="معتمد")*ROW('حجز الإجازات'!$B$5:$B$104)))-5+1))
A6: 3 | B6: ='الموظفون'!B4 | C6: ='الموظفون'!C4 | D6: =IF(SUMPRODUCT(('حجز الإجازات'!$B$5:$B$104='الموظفون'!$B$4)*('حجز الإجازات'!$D$5:$D$104<=D$3)*(('حجز الإجازات'!$E$5:$E$104)>=D$3)*('حجز الإجازات'!$G$5:$G$104="معتمد")*ROW('حجز الإجازات'!$B$5:$B$104))=0,IF(D$3<'الموظفون'!$D$4,"",IF(ISNUMBER(MATCH(D$3,Holidays,0)),"عطلة",IF(MOD(D$3-'الموظفون'!$D$4,CycleWork+CycleRest)<CycleWork,INDEX('الإعدادات والقوائم'!$H$2:$H$4,MOD(INT(MOD(D$3-'الموظفون'!$D$4,CycleWork+CycleRest)*3/CycleWork)+MATCH(StartShift,'الإعدادات والقوائم'!$H$2:$H$4,0)-1,3)+1),"راحة"))),INDEX('حجز الإجازات'!$C$5:$C$104,(SUMPRODUCT(('حجز الإجازات'!$B$5:$B$104='الموظفون'!$B$4)*('حجز الإجازات'!$D$5:$D$104<=D$3)*(('حجز الإجازات'!$E$5:$E$104)>=D$3)*('حجز الإجازات'!$G$5:$G$104="معتمد")*ROW('حجز الإجازات'!$B$5:$B$104)))-5+1)) | E6: =IF(SUMPRODUCT(('حجز الإجازات'!$B$5:$B$104='الموظفون'!$B$4)*('حجز الإجازات'!$D$5:$D$104<=E$3)*(('حجز الإجازات'!$E$5:$E$104)>=E$3)*('حجز الإجازات'!$G$5:$G$104="معتمد")*ROW('حجز الإجازات'!$B$5:$B$104))=0,IF(E$3<'الموظفون'!$D$4,"",IF(ISNUMBER(MATCH(E$3,Holidays,0)),"عطلة",IF(MOD(E$3-'الموظفون'!$D$4,CycleWork+CycleRest)<CycleWork,INDEX('الإعدادات والقوائم'!$H$2:$H$4,MOD(INT(MOD(E$3-'الموظفون'!$D$4,CycleWork+CycleRest)*3/CycleWork)+MATCH(StartShift,'الإعدادات والقوائم'!$H$2:$H$4,0)-1,3)+1),"راحة"))),INDEX('حجز الإجازات'!$C$5:$C$104,(SUMPRODUCT(('حجز الإجازات'!$B$5:$B$104='الموظفون'!$B$4)*('حجز الإجازات'!$D$5:$D$104<=E$3)*(('حجز الإجازات'!$E$5:$E$104)>=E$3)*('حجز الإجازات'!$G$5:$G$104="معتمد")*ROW('حجز الإجازات'!$B$5:$B$104)))-5+1)) | F6: =IF(SUMPRODUCT(('حجز الإجازات'!$B$5:$B$104='الموظفون'!$B$4)*('حجز الإجازات'!$D$5:$D$104<=F$3)*(('حجز الإجازات'!$E$5:$E$104)>=F$3)*('حجز الإجازات'!$G$5:$G$104="معتمد")*ROW('حجز الإجازات'!$B$5:$B$104))=0,IF(F$3<'الموظفون'!$D$4,"",IF(ISNUMBER(MATCH(F$3,Holidays,0)),"عطلة",IF(MOD(F$3-'الموظفون'!$D$4,CycleWork+CycleRest)<CycleWork,INDEX('الإعدادات والقوائم'!$H$2:$H$4,MOD(INT(MOD(F$3-'الموظفون'!$D$4,CycleWork+CycleRest)*3/CycleWork)+MATCH(StartShift,'الإعدادات والقوائم'!$H$2:$H$4,0)-1,3)+1),"راحة"))),INDEX('حجز الإجازات'!$C$5:$C$104,(SUMPRODUCT(('حجز الإجازات'!$B$5:$B$104='الموظفون'!$B$4)*('حجز الإجازات'!$D$5:$D$104<=F$3)*(('حجز الإجازات'!$E$5:$E$104)>=F$3)*('حجز الإجازات'!$G$5:$G$104="معتمد")*ROW('حجز الإجازات'!$B$5:$B$104)))-5+1)) | G6: =IF(SUMPRODUCT(('حجز الإجازات'!$B$5:$B$104='الموظفون'!$B$4)*('حجز الإجازات'!$D$5:$D$104<=G$3)*(('حجز الإجازات'!$E$5:$E$104)>=G$3)*('حجز الإجازات'!$G$5:$G$104="معتمد")*ROW('حجز الإجازات'!$B$5:$B$104))=0,IF(G$3<'الموظفون'!$D$4,"",IF(ISNUMBER(MATCH(G$3,Holidays,0)),"عطلة",IF(MOD(G$3-'الموظفون'!$D$4,CycleWork+CycleRest)<CycleWork,INDEX('الإعدادات والقوائم'!$H$2:$H$4,MOD(INT(MOD(G$3-'الموظفون'!$D$4,CycleWork+CycleRest)*3/CycleWork)+MATCH(StartShift,'الإعدادات والقوائم'!$H$2:$H$4,0)-1,3)+1),"راحة"))),INDEX('حجز الإجازات'!$C$5:$C$104,(SUMPRODUCT(('حجز الإجازات'!$B$5:$B$104='الموظفون'!$B$4)*('حجز الإجازات'!$D$5:$D$104<=G$3)*(('حجز الإجازات'!$E$5:$E$104)>=G$3)*('حجز الإجازات'!$G$5:$G$104="معتمد")*ROW('حجز الإجازات'!$B$5:$B$104)))-5+1)) | H6: =IF(SUMPRODUCT(('حجز الإجازات'!$B$5:$B$104='الموظفون'!$B$4)*('حجز الإجازات'!$D$5:$D$104<=H$3)*(('حجز الإجازات'!$E$5:$E$104)>=H$3)*('حجز الإجازات'!$G$5:$G$104="معتمد")*ROW('حجز الإجازات'!$B$5:$B$104))=0,IF(H$3<'الموظفون'!$D$4,"",IF(ISNUMBER(MATCH(H$3,Holidays,0)),"عطلة",IF(MOD(H$3-'الموظفون'!$D$4,CycleWork+CycleRest)<CycleWork,INDEX('الإعدادات والقوائم'!$H$2:$H$4,MOD(INT(MOD(H$3-'الموظفون'!$D$4,CycleWork+CycleRest)*3/CycleWork)+MATCH(StartShift,'الإعدادات والقوائم'!$H$2:$H$4,0)-1,3)+1),"راحة"))),INDEX('حجز الإجازات'!$C$5:$C$104,(SUMPRODUCT(('حجز الإجازات'!$B$5:$B$104='الموظفون'!$B$4)*('حجز الإجازات'!$D$5:$D$104<=H$3)*(('حجز الإجازات'!$E$5:$E$104)>=H$3)*('حجز الإجازات'!$G$5:$G$104="معتمد")*ROW('حجز الإجازات'!$B$5:$B$104)))-5+1)) | I6: =IF(SUMPRODUCT(('حجز الإجازات'!$B$5:$B$104='الموظفون'!$B$4)*('حجز الإجازات'!$D$5:$D$104<=I$3)*(('حجز الإجازات'!$E$5:$E$104)>=I$3)*('حجز الإجازات'!$G$5:$G$104="معتمد")*ROW('حجز الإجازات'!$B$5:$B$104))=0,IF(I$3<'الموظفون'!$D$4,"",IF(ISNUMBER(MATCH(I$3,Holidays,0)),"عطلة",IF(MOD(I$3-'الموظفون'!$D$4,CycleWork+CycleRest)<CycleWork,INDEX('الإعدادات والقوائم'!$H$2:$H$4,MOD(INT(MOD(I$3-'الموظفون'!$D$4,CycleWork+CycleRest)*3/CycleWork)+MATCH(StartShift,'الإعدادات والقوائم'!$H$2:$H$4,0)-1,3)+1),"راحة"))),INDEX('حجز الإجازات'!$C$5:$C$104,(SUMPRODUCT(('حجز الإجازات'!$B$5:$B$104='الموظفون'!$B$4)*('حجز الإجازات'!$D$5:$D$104<=I$3)*(('حجز الإجازات'!$E$5:$E$104)>=I$3)*('حجز الإجازات'!$G$5:$G$104="معتمد")*ROW('حجز الإجازات'!$B$5:$B$104)))-5+1)) | J6: =IF(SUMPRODUCT(('حجز الإجازات'!$B$5:$B$104='الموظفون'!$B$4)*('حجز الإجازات'!$D$5:$D$104<=J$3)*(('حجز الإجازات'!$E$5:$E$104)>=J$3)*('حجز الإجازات'!$G$5:$G$104="معتمد")*ROW('حجز الإجازات'!$B$5:$B$104))=0,IF(J$3<'الموظفون'!$D$4,"",IF(ISNUMBER(MATCH(J$3,Holidays,0)),"عطلة",IF(MOD(J$3-'الموظفون'!$D$4,CycleWork+CycleRest)<CycleWork,INDEX('الإعدادات والقوائم'!$H$2:$H$4,MOD(INT(MOD(J$3-'الموظفون'!$D$4,CycleWork+CycleRest)*3/CycleWork)+MATCH(StartShift,'الإعدادات والقوائم'!$H$2:$H$4,0)-1,3)+1),"راحة"))),INDEX('حجز الإجازات'!$C$5:$C$104,(SUMPRODUCT(('حجز الإجازات'!$B$5:$B$104='الموظفون'!$B$4)*('حجز الإجازات'!$D$5:$D$104<=J$3)*(('حجز الإجازات'!$E$5:$E$104)>=J$3)*('حجز الإجازات'!$G$5:$G$104="معتمد")*ROW('حجز الإجازات'!$B$5:$B$104)))-5+1)) | K6: =IF(SUMPRODUCT(('حجز الإجازات'!$B$5:$B$104='الموظفون'!$B$4)*('حجز الإجازات'!$D$5:$D$104<=K$3)*(('حجز الإجازات'!$E$5:$E$104)>=K$3)*('حجز الإجازات'!$G$5:$G$104="معتمد")*ROW('حجز الإجازات'!$B$5:$B$104))=0,IF(K$3<'الموظفون'!$D$4,"",IF(ISNUMBER(MATCH(K$3,Holidays,0)),"عطلة",IF(MOD(K$3-'الموظفون'!$D$4,CycleWork+CycleRest)<CycleWork,INDEX('الإعدادات والقوائم'!$H$2:$H$4,MOD(INT(MOD(K$3-'الموظفون'!$D$4,CycleWork+CycleRest)*3/CycleWork)+MATCH(StartShift,'الإعدادات والقوائم'!$H$2:$H$4,0)-1,3)+1),"راحة"))),INDEX('حجز الإجازات'!$C$5:$C$104,(SUMPRODUCT(('حجز الإجازات'!$B$5:$B$104='الموظفون'!$B$4)*('حجز الإجازات'!$D$5:$D$104<=K$3)*(('حجز الإجازات'!$E$5:$E$104)>=K$3)*('حجز الإجازات'!$G$5:$G$104="معتمد")*ROW('حجز الإجازات'!$B$5:$B$104)))-5+1)) | ... ND6: =IF(SUMPRODUCT(('حجز الإجازات'!$B$5:$B$104='الموظفون'!$B$4)*('حجز الإجازات'!$D$5:$D$104<=ND$3)*(('حجز الإجازات'!$E$5:$E$104)>=ND$3)*('حجز الإجازات'!$G$5:$G$104="معتمد")*ROW('حجز الإجازات'!$B$5:$B$104))=0,IF(ND$3<'الموظفون'!$D$4,"",IF(ISNUMBER(MATCH(ND$3,Holidays,0)),"عطلة",IF(MOD(ND$3-'الموظفون'!$D$4,CycleWork+CycleRest)<CycleWork,INDEX('الإعدادات والقوائم'!$H$2:$H$4,MOD(INT(MOD(ND$3-'الموظفون'!$D$4,CycleWork+CycleRest)*3/CycleWork)+MATCH(StartShift,'الإعدادات والقوائم'!$H$2:$H$4,0)-1,3)+1),"راحة"))),INDEX('حجز الإجازات'!$C$5:$C$104,(SUMPRODUCT(('حجز الإجازات'!$B$5:$B$104='الموظفون'!$B$4)*('حجز الإجازات'!$D$5:$D$104<=ND$3)*(('حجز الإجازات'!$E$5:$E$104)>=ND$3)*('حجز الإجازات'!$G$5:$G$104="معتمد")*ROW('حجز الإجازات'!$B$5:$B$104)))-5+1))
